Workbook

Sheet shadow
A1: Shadow Empresa: | AN1: Sim
B3: ANTERIOR | C3: Memoria Anteior | E3: ANO 1 | F3: ANO 2 | G3: ANO 3 | H3: Memoria Atual | I3: Memoria Atual Ajustada | J3: Retirar | K3: Retirar | L3: Retirar | M3: Retirar | N3: Adicionar | O3: Adicionar | P3: Adicionar | Q3: Adicionar | T3: ANTERIOR | U3: Memoria Anteior | W3: ATUAL 1 | X3: ATUAL 2 | Y3: ATUAL 3 | Z3: Memoria Atual | AA3: Memoria Atual Ajustada | AB3: Inversor de Sinal | AC3: Retirar | AD3: Retirar | AE3: Retirar | AF3: Retirar | AG3: Adicionar | AH3: Adicionar | AI3: Adicionar | AJ3: Adicionar
A4: ATIVO | B4: =B2 -> 0 | E4: =E2 -> 0 | F4: =F2 -> 0 | G4: =G2 -> 0 | S4: DEMONSTRAÇÃO DE RESULTADOS | T4: =+B4 -> 0 | W4: =+E4 -> 0 | X4: =+F4 -> 0 | Y4: =+G4 -> 0
A5: Caixa | B5: =IFERROR(SUMIFS(INDEX(rastreabilidade!$F:$H,0,MATCH($B$2,rastreabilidade!$F$1:$H$1,0)),rastreabilidade!$K:$K,$A5,rastreabilidade!$D:$D,"Sim"),0) -> 0 | E5: =IFERROR(SUMIFS(INDEX(rastreabilidade!$F:$H,0,MATCH(E$3,rastreabilidade!$F$1:$H$1,0)),rastreabilidade!$N:$N,$AM5),0) +IF($N5="",0,IFERROR(SUMIFS(INDEX(rastreabilidade!$F:$H,0,MATCH(E$3,rastreabilidade!$F$1:$H$1,0)),rastreabilidade!$M:$M,$N5),0)) +IF($O5="",0,IFERROR(SUMIFS(INDEX(rastreabilidade!$F:$H,0,MATCH(E$3,rastreabilidade!$F$1:$H$1,0)),rastreabilidade!$M:$M,$O5),0)) +IF($P5="",0,IFERROR(SUMIFS(INDEX(rastreabilidade!$F:$H,0,MATCH(E$3,rastreabilidade!$F$1:$H$1,0)),rastreabilidade!$M:$M,$P5),0)) +IF($Q5="",0,IFERROR(SUMIFS(INDEX(rastreabilidade!$F:$H,0,MATCH(E$3,rastreabilidade!$F$1:$H$1,0)),rastreabilidade!$M:$M,$Q5),0)) -IF($J5="",0,IFERROR(SUMIFS(INDEX(rastreabilidade!$F:$H,0,MATCH(E$3,rastreabilidade!$F$1:$H$1,0)),rastreabilidade!$M:$M,$J5,rastreabilidade!$N:$N,$AM5),0)) -IF($K5="",0,IFERROR(SUMIFS(INDEX(rastreabilidade!$F:$H,0,MATCH(E$3,rastreabilidade!$F$1:$H$1,0)),rastreabilidade!$M:$M,$K5,rastreabilidade!$N:$N,$AM5),0)) -IF($L5="",0,IFERROR(SUMIFS(INDEX(rastreabilidade!$F:$H,0,MATCH(E$3,rastreabilidade!$F$1:$H$1,0)),rastreabilidade!$M:$M,$L5,rastreabilidade!$N:$N,$AM5),0)) -IF($M5="",0,IFERROR(SUMIFS(INDEX(rastreabilidade!$F:$H,0,MATCH(E$3,rastreabilidade!$F$1:$H$1,0)),rastreabilidade!$M:$M,$M5,rastreabilidade!$N:$N,$AM5),0)) -> 0 | F5: =IFERROR(SUMIFS(INDEX(rastreabilidade!$F:$H,0,MATCH(F$3,rastreabilidade!$F$1:$H$1,0)),rastreabilidade!$N:$N,$AM5),0) +IF($N5="",0,IFERROR(SUMIFS(INDEX(rastreabilidade!$F:$H,0,MATCH(F$3,rastreabilidade!$F$1:$H$1,0)),rastreabilidade!$M:$M,$N5),0)) +IF($O5="",0,IFERROR(SUMIFS(INDEX(rastreabilidade!$F:$H,0,MATCH(F$3,rastreabilidade!$F$1:$H$1,0)),rastreabilidade!$M:$M,$O5),0)) +IF($P5="",0,IFERROR(SUMIFS(INDEX(rastreabilidade!$F:$H,0,MATCH(F$3,rastreabilidade!$F$1:$H$1,0)),rastreabilidade!$M:$M,$P5),0)) +IF($Q5="",0,IFERROR(SUMIFS(INDEX(rastreabilidade!$F:$H,0,MATCH(F$3,rastreabilidade!$F$1:$H$1,0)),rastreabilidade!$M:$M,$Q5),0)) -IF($J5="",0,IFERROR(SUMIFS(INDEX(rastreabilidade!$F:$H,0,MATCH(F$3,rastreabilidade!$F$1:$H$1,0)),rastreabilidade!$M:$M,$J5,rastreabilidade!$N:$N,$AM5),0)) -IF($K5="",0,IFERROR(SUMIFS(INDEX(rastreabilidade!$F:$H,0,MATCH(F$3,rastreabilidade!$F$1:$H$1,0)),rastreabilidade!$M:$M,$K5,rastreabilidade!$N:$N,$AM5),0)) -IF($L5="",0,IFERROR(SUMIFS(INDEX(rastreabilidade!$F:$H,0,MATCH(F$3,rastreabilidade!$F$1:$H$1,0)),rastreabilidade!$M:$M,$L5,rastreabilidade!$N:$N,$AM5),0)) -IF($M5="",0,IFERROR(SUMIFS(INDEX(rastreabilidade!$F:$H,0,MATCH(F$3,rastreabilidade!$F$1:$H$1,0)),rastreabilidade!$M:$M,$M5,rastreabilidade!$N:$N,$AM5),0)) -> 0 | G5: =IFERROR(SUMIFS(INDEX(rastreabilidade!$F:$H,0,MATCH(G$3,rastreabilidade!$F$1:$H$1,0)),rastreabilidade!$N:$N,$AM5),0) +IF($N5="",0,IFERROR(SUMIFS(INDEX(rastreabilidade!$F:$H,0,MATCH(G$3,rastreabilidade!$F$1:$H$1,0)),rastreabilidade!$M:$M,$N5),0)) +IF($O5="",0,IFERROR(SUMIFS(INDEX(rastreabilidade!$F:$H,0,MATCH(G$3,rastreabilidade!$F$1:$H$1,0)),rastreabilidade!$M:$M,$O5),0)) +IF($P5="",0,IFERROR(SUMIFS(INDEX(rastreabilidade!$F:$H,0,MATCH(G$3,rastreabilidade!$F$1:$H$1,0)),rastreabilidade!$M:$M,$P5),0)) +IF($Q5="",0,IFERROR(SUMIFS(INDEX(rastreabilidade!$F:$H,0,MATCH(G$3,rastreabilidade!$F$1:$H$1,0)),rastreabilidade!$M:$M,$Q5),0)) -IF($J5="",0,IFERROR(SUMIFS(INDEX(rastreabilidade!$F:$H,0,MATCH(G$3,rastreabilidade!$F$1:$H$1,0)),rastreabilidade!$M:$M,$J5,rastreabilidade!$N:$N,$AM5),0)) -IF($K5="",0,IFERROR(SUMIFS(INDEX(rastreabilidade!$F:$H,0,MATCH(G$3,rastreabilidade!$F$1:$H$1,0)),rastreabilidade!$M:$M,$K5,rastreabilidade!$N:$N,$AM5),0)) -IF($L5="",0,IFERROR(SUMIFS(INDEX(rastreabilidade!$F:$H,0,MATCH(G$3,rastreabilidade!$F$1:$H$1,0)),rastreabilidade!$M:$M,$L5,rastreabilidade!$N:$N,$AM5),0)) -IF($M5="",0,IFERROR(SUMIFS(INDEX(rastreabilidade!$F:$H,0,MATCH(G$3,rastreabilidade!$F$1:$H$1,0)),rastreabilidade!$M:$M,$M5,rastreabilidade!$N:$N,$AM5),0)) -> 0 | I5: {=_xlfn.LET( _xlpm.mem,H5, _xlpm.retiradas,J5:M5, _xlpm.adicoes,N5:Q5, _xlpm.memAjustada,_xlfn.REDUCE(_xlpm.mem,_xlpm.retiradas,_xlfn.LAMBDA(_xlpm.x,_xlpm.y,IF(_xlpm.y<>"",SUBSTITUTE(_xlpm.x," + ("&_xlpm.y&")",""),_xlpm.x))), _xlpm.memRemovida,_xlfn.REDUCE(_xlpm.memAjustada,_xlpm.retiradas,_xlfn.LAMBDA(_xlpm.x,_xlpm.y,IF(_xlpm.y<>"",SUBSTITUTE(_xlpm.x,"("&_xlpm.y&")",""),_xlpm.x))), _xlpm.memSemSinal,IF(OR(LEFT(_xlpm.memRemovida,3)=" + ",LEFT(_xlpm.memRemovida,3)=" - "),MID(_xlpm.memRemovida,4,LEN(_xlpm.memRemovida)),_xlpm.memRemovida), _xlpm.memFinal,IF(OR(RIGHT(_xlpm.memSemSinal,3)=" + ",RIGHT(_xlpm.memSemSinal,3)=" - "),LEFT(_xlpm.memSemSinal,LEN(_xlpm.memSemSinal)-3),_xlpm.memSemSinal), _xlpm.adicoesTxt,_xlfn.TEXTJOIN(" + ",TRUE,IF(_xlpm.adicoes<>"","("&_xlpm.adicoes&")","")), IF(_xlpm.memFinal="",_xlpm.adicoesTxt,IF(_xlpm.adicoesTxt="",_xlpm.memFinal,_xlpm.memFinal&" + "&_xlpm.adicoesTxt)) )} | S5: Vendas Totais | T5: =IFERROR(SUMIFS(INDEX(rastreabilidade!$F:$H,0,MATCH($T$2,rastreabilidade!$F$1:$H$1,0)),rastreabilidade!$K:$K,$S5,rastreabilidade!$D:$D,"Sim"),0) -> 0 | W5: =IFERROR(SUMIFS(INDEX(rastreabilidade!$F:$H,0,MATCH(W$3,rastreabilidade!$F$1:$H$1,0)),rastreabilidade!$N:$N,$AN5),0)*IF($AB5="sim",-1,1) +IF($AG5="",0,IFERROR(SUMIFS(INDEX(rastreabilidade!$F:$H,0,MATCH(W$3,rastreabilidade!$F$1:$H$1,0)),rastreabilidade!$M:$M,$AG5),0)) +IF($AH5="",0,IFERROR(SUMIFS(INDEX(rastreabilidade!$F:$H,0,MATCH(W$3,rastreabilidade!$F$1:$H$1,0)),rastreabilidade!$M:$M,$AH5),0)) +IF($AI5="",0,IFERROR(SUMIFS(INDEX(rastreabilidade!$F:$H,0,MATCH(W$3,rastreabilidade!$F$1:$H$1,0)),rastreabilidade!$M:$M,$AI5),0)) +IF($AJ5="",0,IFERROR(SUMIFS(INDEX(rastreabilidade!$F:$H,0,MATCH(W$3,rastreabilidade!$F$1:$H$1,0)),rastreabilidade!$M:$M,$AJ5),0)) -IF($AC5="",0,IFERROR(SUMIFS(INDEX(rastreabilidade!$F:$H,0,MATCH(W$3,rastreabilidade!$F$1:$H$1,0)),rastreabilidade!$M:$M,$AC5,rastreabilidade!$N:$N,$AN5),0)) -IF($AD5="",0,IFERROR(SUMIFS(INDEX(rastreabilidade!$F:$H,0,MATCH(W$3,rastreabilidade!$F$1:$H$1,0)),rastreabilidade!$M:$M,$AD5,rastreabilidade!$N:$N,$AN5),0)) -IF($AE5="",0,IFERROR(SUMIFS(INDEX(rastreabilidade!$F:$H,0,MATCH(W$3,rastreabilidade!$F$1:$H$1,0)),rastreabilidade!$M:$M,$AE5,rastreabilidade!$N:$N,$AN5),0)) -IF($AF5="",0,IFERROR(SUMIFS(INDEX(rastreabilidade!$F:$H,0,MATCH(W$3,rastreabilidade!$F$1:$H$1,0)),rastreabilidade!$M:$M,$AF5,rastreabilidade!$N:$N,$AN5),0)) -> 0 | X5: =IFERROR(SUMIFS(INDEX(rastreabilidade!$F:$H,0,MATCH(X$3,rastreabilidade!$F$1:$H$1,0)),rastreabilidade!$N:$N,$AN5),0)*IF($AB5="sim",-1,1) +IF($AG5="",0,IFERROR(SUMIFS(INDEX(rastreabilidade!$F:$H,0,MATCH(X$3,rastreabilidade!$F$1:$H$1,0)),rastreabilidade!$M:$M,$AG5),0)) +IF($AH5="",0,IFERROR(SUMIFS(INDEX(rastreabilidade!$F:$H,0,MATCH(X$3,rastreabilidade!$F$1:$H$1,0)),rastreabilidade!$M:$M,$AH5),0)) +IF($AI5="",0,IFERROR(SUMIFS(INDEX(rastreabilidade!$F:$H,0,MATCH(X$3,rastreabilidade!$F$1:$H$1,0)),rastreabilidade!$M:$M,$AI5),0)) +IF($AJ5="",0,IFERROR(SUMIFS(INDEX(rastreabilidade!$F:$H,0,MATCH(X$3,rastreabilidade!$F$1:$H$1,0)),rastreabilidade!$M:$M,$AJ5),0)) -IF($AC5="",0,IFERROR(SUMIFS(INDEX(rastreabilidade!$F:$H,0,MATCH(X$3,rastreabilidade!$F$1:$H$1,0)),rastreabilidade!$M:$M,$AC5,rastreabilidade!$N:$N,$AN5),0)) -IF($AD5="",0,IFERROR(SUMIFS(INDEX(rastreabilidade!$F:$H,0,MATCH(X$3,rastreabilidade!$F$1:$H$1,0)),rastreabilidade!$M:$M,$AD5,rastreabilidade!$N:$N,$AN5),0)) -IF($AE5="",0,IFERROR(SUMIFS(INDEX(rastreabilidade!$F:$H,0,MATCH(X$3,rastreabilidade!$F$1:$H$1,0)),rastreabilidade!$M:$M,$AE5,rastreabilidade!$N:$N,$AN5),0)) -IF($AF5="",0,IFERROR(SUMIFS(INDEX(rastreabilidade!$F:$H,0,MATCH(X$3,rastreabilidade!$F$1:$H$1,0)),rastreabilidade!$M:$M,$AF5,rastreabilidade!$N:$N,$AN5),0)) -> 0 | Y5: =IFERROR(SUMIFS(INDEX(rastreabilidade!$F:$H,0,MATCH(Y$3,rastreabilidade!$F$1:$H$1,0)),rastreabilidade!$N:$N,$AN5),0)*IF($AB5="sim",-1,1) +IF($AG5="",0,IFERROR(SUMIFS(INDEX(rastreabilidade!$F:$H,0,MATCH(Y$3,rastreabilidade!$F$1:$H$1,0)),rastreabilidade!$M:$M,$AG5),0)) +IF($AH5="",0,IFERROR(SUMIFS(INDEX(rastreabilidade!$F:$H,0,MATCH(Y$3,rastreabilidade!$F$1:$H$1,0)),rastreabilidade!$M:$M,$AH5),0)) +IF($AI5="",0,IFERROR(SUMIFS(INDEX(rastreabilidade!$F:$H,0,MATCH(Y$3,rastreabilidade!$F$1:$H$1,0)),rastreabilidade!$M:$M,$AI5),0)) +IF($AJ5="",0,IFERROR(SUMIFS(INDEX(rastreabilidade!$F:$H,0,MATCH(Y$3,rastreabilidade!$F$1:$H$1,0)),rastreabilidade!$M:$M,$AJ5),0)) -IF($AC5="",0,IFERROR(SUMIFS(INDEX(rastreabilidade!$F:$H,0,MATCH(Y$3,rastreabilidade!$F$1:$H$1,0)),rastreabilidade!$M:$M,$AC5,rastreabilidade!$N:$N,$AN5),0)) -IF($AD5="",0,IFERROR(SUMIFS(INDEX(rastreabilidade!$F:$H,0,MATCH(Y$3,rastreabilidade!$F$1:$H$1,0)),rastreabilidade!$M:$M,$AD5,rastreabilidade!$N:$N,$AN5),0)) -IF($AE5="",0,IFERROR(SUMIFS(INDEX(rastreabilidade!$F:$H,0,MATCH(Y$3,rastreabilidade!$F$1:$H$1,0)),rastreabilidade!$M:$M,$AE5,rastreabilidade!$N:$N,$AN5),0)) -IF($AF5="",0,IFERROR(SUMIFS(INDEX(rastreabilidade!$F:$H,0,MATCH(Y$3,rastreabilidade!$F$1:$H$1,0)),rastreabilidade!$M:$M,$AF5,rastreabilidade!$N:$N,$AN5),0)) -> 0 | AA5: {=_xlfn.LET( _xlpm.mem,Z5, _xlpm.retiradas,AC5:AF5, _xlpm.adicoes,AG5:AJ5, _xlpm.memAjustada,_xlfn.REDUCE(_xlpm.mem,_xlpm.retiradas,_xlfn.LAMBDA(_xlpm.x,_xlpm.y,IF(_xlpm.y<>"",SUBSTITUTE(_xlpm.x," + ("&_xlpm.y&")",""),_xlpm.x))), _xlpm.memRemovida,_xlfn.REDUCE(_xlpm.memAjustada,_xlpm.retiradas,_xlfn.LAMBDA(_xlpm.x,_xlpm.y,IF(_xlpm.y<>"",SUBSTITUTE(_xlpm.x,"("&_xlpm.y&")",""),_xlpm.x))), _xlpm.memSemSinal,IF(OR(LEFT(_xlpm.memRemovida,3)=" + ",LEFT(_xlpm.memRemovida,3)=" - "),MID(_xlpm.memRemovida,4,LEN(_xlpm.memRemovida)),_xlpm.memRemovida), _xlpm.memFinal,IF(OR(RIGHT(_xlpm.memSemSinal,3)=" + ",RIGHT(_xlpm.memSemSinal,3)=" - "),LEFT(_xlpm.memSemSinal,LEN(_xlpm.memSemSinal)-3),_xlpm.memSemSinal), _xlpm.adicoesTxt,_xlfn.TEXTJOIN(" + ",TRUE,IF(_xlpm.adicoes<>"","("&_xlpm.adicoes&")","")), IF(_xlpm.memFinal="",_xlpm.adicoesTxt,IF(_xlpm.adicoesTxt="",_xlpm.memFinal,_xlpm.memFinal&" + "&_xlpm.adicoesTxt)) )} | AM5: =_xlfn.TEXTJOIN("|",TRUE,A5,"Ativo","Circulante") -> Caixa|Ativo|Circulante | AN5: =_xlfn.CONCAT(S5,"|","DRE","|","DRE",) -> Vendas Totais|DRE|DRE
A6: Aplicações Financeiras | B6: =IFERROR(SUMIFS(INDEX(rastreabilidade!$F:$H,0,MATCH($B$2,rastreabilidade!$F$1:$H$1,0)),rastreabilidade!$K:$K,$A6,rastreabilidade!$D:$D,"Sim"),0) -> 0 | E6: =IFERROR(SUMIFS(INDEX(rastreabilidade!$F:$H,0,MATCH(E$3,rastreabilidade!$F$1:$H$1,0)),rastreabilidade!$N:$N,$AM6),0) +IF($N6="",0,IFERROR(SUMIFS(INDEX(rastreabilidade!$F:$H,0,MATCH(E$3,rastreabilidade!$F$1:$H$1,0)),rastreabilidade!$M:$M,$N6),0)) +IF($O6="",0,IFERROR(SUMIFS(INDEX(rastreabilidade!$F:$H,0,MATCH(E$3,rastreabilidade!$F$1:$H$1,0)),rastreabilidade!$M:$M,$O6),0)) +IF($P6="",0,IFERROR(SUMIFS(INDEX(rastreabilidade!$F:$H,0,MATCH(E$3,rastreabilidade!$F$1:$H$1,0)),rastreabilidade!$M:$M,$P6),0)) +IF($Q6="",0,IFERROR(SUMIFS(INDEX(rastreabilidade!$F:$H,0,MATCH(E$3,rastreabilidade!$F$1:$H$1,0)),rastreabilidade!$M:$M,$Q6),0)) -IF($J6="",0,IFERROR(SUMIFS(INDEX(rastreabilidade!$F:$H,0,MATCH(E$3,rastreabilidade!$F$1:$H$1,0)),rastreabilidade!$M:$M,$J6,rastreabilidade!$N:$N,$AM6),0)) -IF($K6="",0,IFERROR(SUMIFS(INDEX(rastreabilidade!$F:$H,0,MATCH(E$3,rastreabilidade!$F$1:$H$1,0)),rastreabilidade!$M:$M,$K6,rastreabilidade!$N:$N,$AM6),0)) -IF($L6="",0,IFERROR(SUMIFS(INDEX(rastreabilidade!$F:$H,0,MATCH(E$3,rastreabilidade!$F$1:$H$1,0)),rastreabilidade!$M:$M,$L6,rastreabilidade!$N:$N,$AM6),0)) -IF($M6="",0,IFERROR(SUMIFS(INDEX(rastreabilidade!$F:$H,0,MATCH(E$3,rastreabilidade!$F$1:$H$1,0)),rastreabilidade!$M:$M,$M6,rastreabilidade!$N:$N,$AM6),0)) -> 0 | F6: =IFERROR(SUMIFS(INDEX(rastreabilidade!$F:$H,0,MATCH(F$3,rastreabilidade!$F$1:$H$1,0)),rastreabilidade!$N:$N,$AM6),0) +IF($N6="",0,IFERROR(SUMIFS(INDEX(rastreabilidade!$F:$H,0,MATCH(F$3,rastreabilidade!$F$1:$H$1,0)),rastreabilidade!$M:$M,$N6),0)) +IF($O6="",0,IFERROR(SUMIFS(INDEX(rastreabilidade!$F:$H,0,MATCH(F$3,rastreabilidade!$F$1:$H$1,0)),rastreabilidade!$M:$M,$O6),0)) +IF($P6="",0,IFERROR(SUMIFS(INDEX(rastreabilidade!$F:$H,0,MATCH(F$3,rastreabilidade!$F$1:$H$1,0)),rastreabilidade!$M:$M,$P6),0)) +IF($Q6="",0,IFERROR(SUMIFS(INDEX(rastreabilidade!$F:$H,0,MATCH(F$3,rastreabilidade!$F$1:$H$1,0)),rastreabilidade!$M:$M,$Q6),0)) -IF($J6="",0,IFERROR(SUMIFS(INDEX(rastreabilidade!$F:$H,0,MATCH(F$3,rastreabilidade!$F$1:$H$1,0)),rastreabilidade!$M:$M,$J6,rastreabilidade!$N:$N,$AM6),0)) -IF($K6="",0,IFERROR(SUMIFS(INDEX(rastreabilidade!$F:$H,0,MATCH(F$3,rastreabilidade!$F$1:$H$1,0)),rastreabilidade!$M:$M,$K6,rastreabilidade!$N:$N,$AM6),0)) -IF($L6="",0,IFERROR(SUMIFS(INDEX(rastreabilidade!$F:$H,0,MATCH(F$3,rastreabilidade!$F$1:$H$1,0)),rastreabilidade!$M:$M,$L6,rastreabilidade!$N:$N,$AM6),0)) -IF($M6="",0,IFERROR(SUMIFS(INDEX(rastreabilidade!$F:$H,0,MATCH(F$3,rastreabilidade!$F$1:$H$1,0)),rastreabilidade!$M:$M,$M6,rastreabilidade!$N:$N,$AM6),0)) -> 0 | G6: =IFERROR(SUMIFS(INDEX(rastreabilidade!$F:$H,0,MATCH(G$3,rastreabilidade!$F$1:$H$1,0)),rastreabilidade!$N:$N,$AM6),0) +IF($N6="",0,IFERROR(SUMIFS(INDEX(rastreabilidade!$F:$H,0,MATCH(G$3,rastreabilidade!$F$1:$H$1,0)),rastreabilidade!$M:$M,$N6),0)) +IF($O6="",0,IFERROR(SUMIFS(INDEX(rastreabilidade!$F:$H,0,MATCH(G$3,rastreabilidade!$F$1:$H$1,0)),rastreabilidade!$M:$M,$O6),0)) +IF($P6="",0,IFERROR(SUMIFS(INDEX(rastreabilidade!$F:$H,0,MATCH(G$3,rastreabilidade!$F$1:$H$1,0)),rastreabilidade!$M:$M,$P6),0)) +IF($Q6="",0,IFERROR(SUMIFS(INDEX(rastreabilidade!$F:$H,0,MATCH(G$3,rastreabilidade!$F$1:$H$1,0)),rastreabilidade!$M:$M,$Q6),0)) -IF($J6="",0,IFERROR(SUMIFS(INDEX(rastreabilidade!$F:$H,0,MATCH(G$3,rastreabilidade!$F$1:$H$1,0)),rastreabilidade!$M:$M,$J6,rastreabilidade!$N:$N,$AM6),0)) -IF($K6="",0,IFERROR(SUMIFS(INDEX(rastreabilidade!$F:$H,0,MATCH(G$3,rastreabilidade!$F$1:$H$1,0)),rastreabilidade!$M:$M,$K6,rastreabilidade!$N:$N,$AM6),0)) -IF($L6="",0,IFERROR(SUMIFS(INDEX(rastreabilidade!$F:$H,0,MATCH(G$3,rastreabilidade!$F$1:$H$1,0)),rastreabilidade!$M:$M,$L6,rastreabilidade!$N:$N,$AM6),0)) -IF($M6="",0,IFERROR(SUMIFS(INDEX(rastreabilidade!$F:$H,0,MATCH(G$3,rastreabilidade!$F$1:$H$1,0)),rastreabilidade!$M:$M,$M6,rastreabilidade!$N:$N,$AM6),0)) -> 0 | I6: {=_xlfn.LET( _xlpm.mem,H6, _xlpm.retiradas,J6:M6, _xlpm.adicoes,N6:Q6, _xlpm.memAjustada,_xlfn.REDUCE(_xlpm.mem,_xlpm.retiradas,_xlfn.LAMBDA(_xlpm.x,_xlpm.y,IF(_xlpm.y<>"",SUBSTITUTE(_xlpm.x," + ("&_xlpm.y&")",""),_xlpm.x))), _xlpm.memRemovida,_xlfn.REDUCE(_xlpm.memAjustada,_xlpm.retiradas,_xlfn.LAMBDA(_xlpm.x,_xlpm.y,IF(_xlpm.y<>"",SUBSTITUTE(_xlpm.x,"("&_xlpm.y&")",""),_xlpm.x))), _xlpm.memSemSinal,IF(OR(LEFT(_xlpm.memRemovida,3)=" + ",LEFT(_xlpm.memRemovida,3)=" - "),MID(_xlpm.memRemovida,4,LEN(_xlpm.memRemovida)),_xlpm.memRemovida), _xlpm.memFinal,IF(OR(RIGHT(_xlpm.memSemSinal,3)=" + ",RIGHT(_xlpm.memSemSinal,3)=" - "),LEFT(_xlpm.memSemSinal,LEN(_xlpm.memSemSinal)-3),_xlpm.memSemSinal), _xlpm.adicoesTxt,_xlfn.TEXTJOIN(" + ",TRUE,IF(_xlpm.adicoes<>"","("&_xlpm.adicoes&")","")), IF(_xlpm.memFinal="",_xlpm.adicoesTxt,IF(_xlpm.adicoesTxt="",_xlpm.memFinal,_xlpm.memFinal&" + "&_xlpm.adicoesTxt)) )} | S6: -Impostos | T6: =IFERROR(SUMIFS(INDEX(rastreabilidade!$F:$H,0,MATCH($T$2,rastreabilidade!$F$1:$H$1,0)),rastreabilidade!$K:$K,$S6,rastreabilidade!$D:$D,"Sim"),0) -> 0 | W6: =IFERROR(SUMIFS(INDEX(rastreabilidade!$F:$H,0,MATCH(W$3,rastreabilidade!$F$1:$H$1,0)),rastreabilidade!$N:$N,$AN6),0)*IF($AB6="sim",-1,1) +IF($AG6="",0,IFERROR(SUMIFS(INDEX(rastreabilidade!$F:$H,0,MATCH(W$3,rastreabilidade!$F$1:$H$1,0)),rastreabilidade!$M:$M,$AG6),0)) +IF($AH6="",0,IFERROR(SUMIFS(INDEX(rastreabilidade!$F:$H,0,MATCH(W$3,rastreabilidade!$F$1:$H$1,0)),rastreabilidade!$M:$M,$AH6),0)) +IF($AI6="",0,IFERROR(SUMIFS(INDEX(rastreabilidade!$F:$H,0,MATCH(W$3,rastreabilidade!$F$1:$H$1,0)),rastreabilidade!$M:$M,$AI6),0)) +IF($AJ6="",0,IFERROR(SUMIFS(INDEX(rastreabilidade!$F:$H,0,MATCH(W$3,rastreabilidade!$F$1:$H$1,0)),rastreabilidade!$M:$M,$AJ6),0)) -IF($AC6="",0,IFERROR(SUMIFS(INDEX(rastreabilidade!$F:$H,0,MATCH(W$3,rastreabilidade!$F$1:$H$1,0)),rastreabilidade!$M:$M,$AC6,rastreabilidade!$N:$N,$AN6),0)) -IF($AD6="",0,IFERROR(SUMIFS(INDEX(rastreabilidade!$F:$H,0,MATCH(W$3,rastreabilidade!$F$1:$H$1,0)),rastreabilidade!$M:$M,$AD6,rastreabilidade!$N:$N,$AN6),0)) -IF($AE6="",0,IFERROR(SUMIFS(INDEX(rastreabilidade!$F:$H,0,MATCH(W$3,rastreabilidade!$F$1:$H$1,0)),rastreabilidade!$M:$M,$AE6,rastreabilidade!$N:$N,$AN6),0)) -IF($AF6="",0,IFERROR(SUMIFS(INDEX(rastreabilidade!$F:$H,0,MATCH(W$3,rastreabilidade!$F$1:$H$1,0)),rastreabilidade!$M:$M,$AF6,rastreabilidade!$N:$N,$AN6),0)) -> 0 | X6: =IFERROR(SUMIFS(INDEX(rastreabilidade!$F:$H,0,MATCH(X$3,rastreabilidade!$F$1:$H$1,0)),rastreabilidade!$N:$N,$AN6),0)*IF($AB6="sim",-1,1) +IF($AG6="",0,IFERROR(SUMIFS(INDEX(rastreabilidade!$F:$H,0,MATCH(X$3,rastreabilidade!$F$1:$H$1,0)),rastreabilidade!$M:$M,$AG6),0)) +IF($AH6="",0,IFERROR(SUMIFS(INDEX(rastreabilidade!$F:$H,0,MATCH(X$3,rastreabilidade!$F$1:$H$1,0)),rastreabilidade!$M:$M,$AH6),0)) +IF($AI6="",0,IFERROR(SUMIFS(INDEX(rastreabilidade!$F:$H,0,MATCH(X$3,rastreabilidade!$F$1:$H$1,0)),rastreabilidade!$M:$M,$AI6),0)) +IF($AJ6="",0,IFERROR(SUMIFS(INDEX(rastreabilidade!$F:$H,0,MATCH(X$3,rastreabilidade!$F$1:$H$1,0)),rastreabilidade!$M:$M,$AJ6),0)) -IF($AC6="",0,IFERROR(SUMIFS(INDEX(rastreabilidade!$F:$H,0,MATCH(X$3,rastreabilidade!$F$1:$H$1,0)),rastreabilidade!$M:$M,$AC6,rastreabilidade!$N:$N,$AN6),0)) -IF($AD6="",0,IFERROR(SUMIFS(INDEX(rastreabilidade!$F:$H,0,MATCH(X$3,rastreabilidade!$F$1:$H$1,0)),rastreabilidade!$M:$M,$AD6,rastreabilidade!$N:$N,$AN6),0)) -IF($AE6="",0,IFERROR(SUMIFS(INDEX(rastreabilidade!$F:$H,0,MATCH(X$3,rastreabilidade!$F$1:$H$1,0)),rastreabilidade!$M:$M,$AE6,rastreabilidade!$N:$N,$AN6),0)) -IF($AF6="",0,IFERROR(SUMIFS(INDEX(rastreabilidade!$F:$H,0,MATCH(X$3,rastreabilidade!$F$1:$H$1,0)),rastreabilidade!$M:$M,$AF6,rastreabilidade!$N:$N,$AN6),0)) -> 0 | Y6: =IFERROR(SUMIFS(INDEX(rastreabilidade!$F:$H,0,MATCH(Y$3,rastreabilidade!$F$1:$H$1,0)),rastreabilidade!$N:$N,$AN6),0)*IF($AB6="sim",-1,1) +IF($AG6="",0,IFERROR(SUMIFS(INDEX(rastreabilidade!$F:$H,0,MATCH(Y$3,rastreabilidade!$F$1:$H$1,0)),rastreabilidade!$M:$M,$AG6),0)) +IF($AH6="",0,IFERROR(SUMIFS(INDEX(rastreabilidade!$F:$H,0,MATCH(Y$3,rastreabilidade!$F$1:$H$1,0)),rastreabilidade!$M:$M,$AH6),0)) +IF($AI6="",0,IFERROR(SUMIFS(INDEX(rastreabilidade!$F:$H,0,MATCH(Y$3,rastreabilidade!$F$1:$H$1,0)),rastreabilidade!$M:$M,$AI6),0)) +IF($AJ6="",0,IFERROR(SUMIFS(INDEX(rastreabilidade!$F:$H,0,MATCH(Y$3,rastreabilidade!$F$1:$H$1,0)),rastreabilidade!$M:$M,$AJ6),0)) -IF($AC6="",0,IFERROR(SUMIFS(INDEX(rastreabilidade!$F:$H,0,MATCH(Y$3,rastreabilidade!$F$1:$H$1,0)),rastreabilidade!$M:$M,$AC6,rastreabilidade!$N:$N,$AN6),0)) -IF($AD6="",0,IFERROR(SUMIFS(INDEX(rastreabilidade!$F:$H,0,MATCH(Y$3,rastreabilidade!$F$1:$H$1,0)),rastreabilidade!$M:$M,$AD6,rastreabilidade!$N:$N,$AN6),0)) -IF($AE6="",0,IFERROR(SUMIFS(INDEX(rastreabilidade!$F:$H,0,MATCH(Y$3,rastreabilidade!$F$1:$H$1,0)),rastreabilidade!$M:$M,$AE6,rastreabilidade!$N:$N,$AN6),0)) -IF($AF6="",0,IFERROR(SUMIFS(INDEX(rastreabilidade!$F:$H,0,MATCH(Y$3,rastreabilidade!$F$1:$H$1,0)),rastreabilidade!$M:$M,$AF6,rastreabilidade!$N:$N,$AN6),0)) -> 0 | AA6: {=_xlfn.LET( _xlpm.mem,Z6, _xlpm.retiradas,AC6:AF6, _xlpm.adicoes,AG6:AJ6, _xlpm.memAjustada,_xlfn.REDUCE(_xlpm.mem,_xlpm.retiradas,_xlfn.LAMBDA(_xlpm.x,_xlpm.y,IF(_xlpm.y<>"",SUBSTITUTE(_xlpm.x," + ("&_xlpm.y&")",""),_xlpm.x))), _xlpm.memRemovida,_xlfn.REDUCE(_xlpm.memAjustada,_xlpm.retiradas,_xlfn.LAMBDA(_xlpm.x,_xlpm.y,IF(_xlpm.y<>"",SUBSTITUTE(_xlpm.x,"("&_xlpm.y&")",""),_xlpm.x))), _xlpm.memSemSinal,IF(OR(LEFT(_xlpm.memRemovida,3)=" + ",LEFT(_xlpm.memRemovida,3)=" - "),MID(_xlpm.memRemovida,4,LEN(_xlpm.memRemovida)),_xlpm.memRemovida), _xlpm.memFinal,IF(OR(RIGHT(_xlpm.memSemSinal,3)=" + ",RIGHT(_xlpm.memSemSinal,3)=" - "),LEFT(_xlpm.memSemSinal,LEN(_xlpm.memSemSinal)-3),_xlpm.memSemSinal), _xlpm.adicoesTxt,_xlfn.TEXTJOIN(" + ",TRUE,IF(_xlpm.adicoes<>"","("&_xlpm.adicoes&")","")), IF(_xlpm.memFinal="",_xlpm.adicoesTxt,IF(_xlpm.adicoesTxt="",_xlpm.memFinal,_xlpm.memFinal&" + "&_xlpm.adicoesTxt)) )} | AM6: =_xlfn.TEXTJOIN("|",TRUE,A6,"Ativo","Circulante") -> Aplicações Financeiras|Ativo|Circulante | AN6: =_xlfn.CONCAT(S6,"|","DRE","|","DRE",) -> -Impostos|DRE|DRE
A7: Disponibilidades | B7: =+B6+B5 -> 0 | E7: =+E6+E5 -> 0 | F7: =+F6+F5 -> 0 | G7: =+G6+G5 -> 0 | S7: Vendas Líquidas | T7: =+T5-T6 -> 0 | W7: =+W5-W6 -> 0 | X7: =+X5-X6 -> 0 | Y7: =+Y5-Y6 -> 0 | AM7: =_xlfn.TEXTJOIN("|",TRUE,A7,"Ativo","Circulante") -> Disponibilidades|Ativo|Circulante | AN7: =_xlfn.CONCAT(S7,"|","DRE","|","DRE",) -> Vendas Líquidas|DRE|DRE
A8: Clientes | B8: =IFERROR(SUMIFS(INDEX(rastreabilidade!$F:$H,0,MATCH($B$2,rastreabilidade!$F$1:$H$1,0)),rastreabilidade!$K:$K,$A8,rastreabilidade!$D:$D,"Sim"),0) -> 0 | E8: =IFERROR(SUMIFS(INDEX(rastreabilidade!$F:$H,0,MATCH(E$3,rastreabilidade!$F$1:$H$1,0)),rastreabilidade!$N:$N,$AM8),0) +IF($N8="",0,IFERROR(SUMIFS(INDEX(rastreabilidade!$F:$H,0,MATCH(E$3,rastreabilidade!$F$1:$H$1,0)),rastreabilidade!$M:$M,$N8),0)) +IF($O8="",0,IFERROR(SUMIFS(INDEX(rastreabilidade!$F:$H,0,MATCH(E$3,rastreabilidade!$F$1:$H$1,0)),rastreabilidade!$M:$M,$O8),0)) +IF($P8="",0,IFERROR(SUMIFS(INDEX(rastreabilidade!$F:$H,0,MATCH(E$3,rastreabilidade!$F$1:$H$1,0)),rastreabilidade!$M:$M,$P8),0)) +IF($Q8="",0,IFERROR(SUMIFS(INDEX(rastreabilidade!$F:$H,0,MATCH(E$3,rastreabilidade!$F$1:$H$1,0)),rastreabilidade!$M:$M,$Q8),0)) -IF($J8="",0,IFERROR(SUMIFS(INDEX(rastreabilidade!$F:$H,0,MATCH(E$3,rastreabilidade!$F$1:$H$1,0)),rastreabilidade!$M:$M,$J8,rastreabilidade!$N:$N,$AM8),0)) -IF($K8="",0,IFERROR(SUMIFS(INDEX(rastreabilidade!$F:$H,0,MATCH(E$3,rastreabilidade!$F$1:$H$1,0)),rastreabilidade!$M:$M,$K8,rastreabilidade!$N:$N,$AM8),0)) -IF($L8="",0,IFERROR(SUMIFS(INDEX(rastreabilidade!$F:$H,0,MATCH(E$3,rastreabilidade!$F$1:$H$1,0)),rastreabilidade!$M:$M,$L8,rastreabilidade!$N:$N,$AM8),0)) -IF($M8="",0,IFERROR(SUMIFS(INDEX(rastreabilidade!$F:$H,0,MATCH(E$3,rastreabilidade!$F$1:$H$1,0)),rastreabilidade!$M:$M,$M8,rastreabilidade!$N:$N,$AM8),0)) -> 0 | F8: =IFERROR(SUMIFS(INDEX(rastreabilidade!$F:$H,0,MATCH(F$3,rastreabilidade!$F$1:$H$1,0)),rastreabilidade!$N:$N,$AM8),0) +IF($N8="",0,IFERROR(SUMIFS(INDEX(rastreabilidade!$F:$H,0,MATCH(F$3,rastreabilidade!$F$1:$H$1,0)),rastreabilidade!$M:$M,$N8),0)) +IF($O8="",0,IFERROR(SUMIFS(INDEX(rastreabilidade!$F:$H,0,MATCH(F$3,rastreabilidade!$F$1:$H$1,0)),rastreabilidade!$M:$M,$O8),0)) +IF($P8="",0,IFERROR(SUMIFS(INDEX(rastreabilidade!$F:$H,0,MATCH(F$3,rastreabilidade!$F$1:$H$1,0)),rastreabilidade!$M:$M,$P8),0)) +IF($Q8="",0,IFERROR(SUMIFS(INDEX(rastreabilidade!$F:$H,0,MATCH(F$3,rastreabilidade!$F$1:$H$1,0)),rastreabilidade!$M:$M,$Q8),0)) -IF($J8="",0,IFERROR(SUMIFS(INDEX(rastreabilidade!$F:$H,0,MATCH(F$3,rastreabilidade!$F$1:$H$1,0)),rastreabilidade!$M:$M,$J8,rastreabilidade!$N:$N,$AM8),0)) -IF($K8="",0,IFERROR(SUMIFS(INDEX(rastreabilidade!$F:$H,0,MATCH(F$3,rastreabilidade!$F$1:$H$1,0)),rastreabilidade!$M:$M,$K8,rastreabilidade!$N:$N,$AM8),0)) -IF($L8="",0,IFERROR(SUMIFS(INDEX(rastreabilidade!$F:$H,0,MATCH(F$3,rastreabilidade!$F$1:$H$1,0)),rastreabilidade!$M:$M,$L8,rastreabilidade!$N:$N,$AM8),0)) -IF($M8="",0,IFERROR(SUMIFS(INDEX(rastreabilidade!$F:$H,0,MATCH(F$3,rastreabilidade!$F$1:$H$1,0)),rastreabilidade!$M:$M,$M8,rastreabilidade!$N:$N,$AM8),0)) -> 0 | G8: =IFERROR(SUMIFS(INDEX(rastreabilidade!$F:$H,0,MATCH(G$3,rastreabilidade!$F$1:$H$1,0)),rastreabilidade!$N:$N,$AM8),0) +IF($N8="",0,IFERROR(SUMIFS(INDEX(rastreabilidade!$F:$H,0,MATCH(G$3,rastreabilidade!$F$1:$H$1,0)),rastreabilidade!$M:$M,$N8),0)) +IF($O8="",0,IFERROR(SUMIFS(INDEX(rastreabilidade!$F:$H,0,MATCH(G$3,rastreabilidade!$F$1:$H$1,0)),rastreabilidade!$M:$M,$O8),0)) +IF($P8="",0,IFERROR(SUMIFS(INDEX(rastreabilidade!$F:$H,0,MATCH(G$3,rastreabilidade!$F$1:$H$1,0)),rastreabilidade!$M:$M,$P8),0)) +IF($Q8="",0,IFERROR(SUMIFS(INDEX(rastreabilidade!$F:$H,0,MATCH(G$3,rastreabilidade!$F$1:$H$1,0)),rastreabilidade!$M:$M,$Q8),0)) -IF($J8="",0,IFERROR(SUMIFS(INDEX(rastreabilidade!$F:$H,0,MATCH(G$3,rastreabilidade!$F$1:$H$1,0)),rastreabilidade!$M:$M,$J8,rastreabilidade!$N:$N,$AM8),0)) -IF($K8="",0,IFERROR(SUMIFS(INDEX(rastreabilidade!$F:$H,0,MATCH(G$3,rastreabilidade!$F$1:$H$1,0)),rastreabilidade!$M:$M,$K8,rastreabilidade!$N:$N,$AM8),0)) -IF($L8="",0,IFERROR(SUMIFS(INDEX(rastreabilidade!$F:$H,0,MATCH(G$3,rastreabilidade!$F$1:$H$1,0)),rastreabilidade!$M:$M,$L8,rastreabilidade!$N:$N,$AM8),0)) -IF($M8="",0,IFERROR(SUMIFS(INDEX(rastreabilidade!$F:$H,0,MATCH(G$3,rastreabilidade!$F$1:$H$1,0)),rastreabilidade!$M:$M,$M8,rastreabilidade!$N:$N,$AM8),0)) -> 0 | I8: {=_xlfn.LET( _xlpm.mem,H8, _xlpm.retiradas,J8:M8, _xlpm.adicoes,N8:Q8, _xlpm.memAjustada,_xlfn.REDUCE(_xlpm.mem,_xlpm.retiradas,_xlfn.LAMBDA(_xlpm.x,_xlpm.y,IF(_xlpm.y<>"",SUBSTITUTE(_xlpm.x," + ("&_xlpm.y&")",""),_xlpm.x))), _xlpm.memRemovida,_xlfn.REDUCE(_xlpm.memAjustada,_xlpm.retiradas,_xlfn.LAMBDA(_xlpm.x,_xlpm.y,IF(_xlpm.y<>"",SUBSTITUTE(_xlpm.x,"("&_xlpm.y&")",""),_xlpm.x))), _xlpm.memSemSinal,IF(OR(LEFT(_xlpm.memRemovida,3)=" + ",LEFT(_xlpm.memRemovida,3)=" - "),MID(_xlpm.memRemovida,4,LEN(_xlpm.memRemovida)),_xlpm.memRemovida), _xlpm.memFinal,IF(OR(RIGHT(_xlpm.memSemSinal,3)=" + ",RIGHT(_xlpm.memSemSinal,3)=" - "),LEFT(_xlpm.memSemSinal,LEN(_xlpm.memSemSinal)-3),_xlpm.memSemSinal), _xlpm.adicoesTxt,_xlfn.TEXTJOIN(" + ",TRUE,IF(_xlpm.adicoes<>"","("&_xlpm.adicoes&")","")), IF(_xlpm.memFinal="",_xlpm.adicoesTxt,IF(_xlpm.adicoesTxt="",_xlpm.memFinal,_xlpm.memFinal&" + "&_xlpm.adicoesTxt)) )} | S8: -Custo de Produtos Vendidos | T8: =IFERROR(SUMIFS(INDEX(rastreabilidade!$F:$H,0,MATCH($T$2,rastreabilidade!$F$1:$H$1,0)),rastreabilidade!$K:$K,$S8,rastreabilidade!$D:$D,"Sim"),0) -> 0 | W8: =IFERROR(SUMIFS(INDEX(rastreabilidade!$F:$H,0,MATCH(W$3,rastreabilidade!$F$1:$H$1,0)),rastreabilidade!$N:$N,$AN8),0)*IF($AB8="sim",-1,1) +IF($AG8="",0,IFERROR(SUMIFS(INDEX(rastreabilidade!$F:$H,0,MATCH(W$3,rastreabilidade!$F$1:$H$1,0)),rastreabilidade!$M:$M,$AG8),0)) +IF($AH8="",0,IFERROR(SUMIFS(INDEX(rastreabilidade!$F:$H,0,MATCH(W$3,rastreabilidade!$F$1:$H$1,0)),rastreabilidade!$M:$M,$AH8),0)) +IF($AI8="",0,IFERROR(SUMIFS(INDEX(rastreabilidade!$F:$H,0,MATCH(W$3,rastreabilidade!$F$1:$H$1,0)),rastreabilidade!$M:$M,$AI8),0)) +IF($AJ8="",0,IFERROR(SUMIFS(INDEX(rastreabilidade!$F:$H,0,MATCH(W$3,rastreabilidade!$F$1:$H$1,0)),rastreabilidade!$M:$M,$AJ8),0)) -IF($AC8="",0,IFERROR(SUMIFS(INDEX(rastreabilidade!$F:$H,0,MATCH(W$3,rastreabilidade!$F$1:$H$1,0)),rastreabilidade!$M:$M,$AC8,rastreabilidade!$N:$N,$AN8),0)) -IF($AD8="",0,IFERROR(SUMIFS(INDEX(rastreabilidade!$F:$H,0,MATCH(W$3,rastreabilidade!$F$1:$H$1,0)),rastreabilidade!$M:$M,$AD8,rastreabilidade!$N:$N,$AN8),0)) -IF($AE8="",0,IFERROR(SUMIFS(INDEX(rastreabilidade!$F:$H,0,MATCH(W$3,rastreabilidade!$F$1:$H$1,0)),rastreabilidade!$M:$M,$AE8,rastreabilidade!$N:$N,$AN8),0)) -IF($AF8="",0,IFERROR(SUMIFS(INDEX(rastreabilidade!$F:$H,0,MATCH(W$3,rastreabilidade!$F$1:$H$1,0)),rastreabilidade!$M:$M,$AF8,rastreabilidade!$N:$N,$AN8),0)) -> 0 | X8: =IFERROR(SUMIFS(INDEX(rastreabilidade!$F:$H,0,MATCH(X$3,rastreabilidade!$F$1:$H$1,0)),rastreabilidade!$N:$N,$AN8),0)*IF($AB8="sim",-1,1) +IF($AG8="",0,IFERROR(SUMIFS(INDEX(rastreabilidade!$F:$H,0,MATCH(X$3,rastreabilidade!$F$1:$H$1,0)),rastreabilidade!$M:$M,$AG8),0)) +IF($AH8="",0,IFERROR(SUMIFS(INDEX(rastreabilidade!$F:$H,0,MATCH(X$3,rastreabilidade!$F$1:$H$1,0)),rastreabilidade!$M:$M,$AH8),0)) +IF($AI8="",0,IFERROR(SUMIFS(INDEX(rastreabilidade!$F:$H,0,MATCH(X$3,rastreabilidade!$F$1:$H$1,0)),rastreabilidade!$M:$M,$AI8),0)) +IF($AJ8="",0,IFERROR(SUMIFS(INDEX(rastreabilidade!$F:$H,0,MATCH(X$3,rastreabilidade!$F$1:$H$1,0)),rastreabilidade!$M:$M,$AJ8),0)) -IF($AC8="",0,IFERROR(SUMIFS(INDEX(rastreabilidade!$F:$H,0,MATCH(X$3,rastreabilidade!$F$1:$H$1,0)),rastreabilidade!$M:$M,$AC8,rastreabilidade!$N:$N,$AN8),0)) -IF($AD8="",0,IFERROR(SUMIFS(INDEX(rastreabilidade!$F:$H,0,MATCH(X$3,rastreabilidade!$F$1:$H$1,0)),rastreabilidade!$M:$M,$AD8,rastreabilidade!$N:$N,$AN8),0)) -IF($AE8="",0,IFERROR(SUMIFS(INDEX(rastreabilidade!$F:$H,0,MATCH(X$3,rastreabilidade!$F$1:$H$1,0)),rastreabilidade!$M:$M,$AE8,rastreabilidade!$N:$N,$AN8),0)) -IF($AF8="",0,IFERROR(SUMIFS(INDEX(rastreabilidade!$F:$H,0,MATCH(X$3,rastreabilidade!$F$1:$H$1,0)),rastreabilidade!$M:$M,$AF8,rastreabilidade!$N:$N,$AN8),0)) -> 0 | Y8: =IFERROR(SUMIFS(INDEX(rastreabilidade!$F:$H,0,MATCH(Y$3,rastreabilidade!$F$1:$H$1,0)),rastreabilidade!$N:$N,$AN8),0)*IF($AB8="sim",-1,1) +IF($AG8="",0,IFERROR(SUMIFS(INDEX(rastreabilidade!$F:$H,0,MATCH(Y$3,rastreabilidade!$F$1:$H$1,0)),rastreabilidade!$M:$M,$AG8),0)) +IF($AH8="",0,IFERROR(SUMIFS(INDEX(rastreabilidade!$F:$H,0,MATCH(Y$3,rastreabilidade!$F$1:$H$1,0)),rastreabilidade!$M:$M,$AH8),0)) +IF($AI8="",0,IFERROR(SUMIFS(INDEX(rastreabilidade!$F:$H,0,MATCH(Y$3,rastreabilidade!$F$1:$H$1,0)),rastreabilidade!$M:$M,$AI8),0)) +IF($AJ8="",0,IFERROR(SUMIFS(INDEX(rastreabilidade!$F:$H,0,MATCH(Y$3,rastreabilidade!$F$1:$H$1,0)),rastreabilidade!$M:$M,$AJ8),0)) -IF($AC8="",0,IFERROR(SUMIFS(INDEX(rastreabilidade!$F:$H,0,MATCH(Y$3,rastreabilidade!$F$1:$H$1,0)),rastreabilidade!$M:$M,$AC8,rastreabilidade!$N:$N,$AN8),0)) -IF($AD8="",0,IFERROR(SUMIFS(INDEX(rastreabilidade!$F:$H,0,MATCH(Y$3,rastreabilidade!$F$1:$H$1,0)),rastreabilidade!$M:$M,$AD8,rastreabilidade!$N:$N,$AN8),0)) -IF($AE8="",0,IFERROR(SUMIFS(INDEX(rastreabilidade!$F:$H,0,MATCH(Y$3,rastreabilidade!$F$1:$H$1,0)),rastreabilidade!$M:$M,$AE8,rastreabilidade!$N:$N,$AN8),0)) -IF($AF8="",0,IFERROR(SUMIFS(INDEX(rastreabilidade!$F:$H,0,MATCH(Y$3,rastreabilidade!$F$1:$H$1,0)),rastreabilidade!$M:$M,$AF8,rastreabilidade!$N:$N,$AN8),0)) -> 0 | AA8: {=_xlfn.LET( _xlpm.mem,Z8, _xlpm.retiradas,AC8:AF8, _xlpm.adicoes,AG8:AJ8, _xlpm.memAjustada,_xlfn.REDUCE(_xlpm.mem,_xlpm.retiradas,_xlfn.LAMBDA(_xlpm.x,_xlpm.y,IF(_xlpm.y<>"",SUBSTITUTE(_xlpm.x," + ("&_xlpm.y&")",""),_xlpm.x))), _xlpm.memRemovida,_xlfn.REDUCE(_xlpm.memAjustada,_xlpm.retiradas,_xlfn.LAMBDA(_xlpm.x,_xlpm.y,IF(_xlpm.y<>"",SUBSTITUTE(_xlpm.x,"("&_xlpm.y&")",""),_xlpm.x))), _xlpm.memSemSinal,IF(OR(LEFT(_xlpm.memRemovida,3)=" + ",LEFT(_xlpm.memRemovida,3)=" - "),MID(_xlpm.memRemovida,4,LEN(_xlpm.memRemovida)),_xlpm.memRemovida), _xlpm.memFinal,IF(OR(RIGHT(_xlpm.memSemSinal,3)=" + ",RIGHT(_xlpm.memSemSinal,3)=" - "),LEFT(_xlpm.memSemSinal,LEN(_xlpm.memSemSinal)-3),_xlpm.memSemSinal), _xlpm.adicoesTxt,_xlfn.TEXTJOIN(" + ",TRUE,IF(_xlpm.adicoes<>"","("&_xlpm.adicoes&")","")), IF(_xlpm.memFinal="",_xlpm.adicoesTxt,IF(_xlpm.adicoesTxt="",_xlpm.memFinal,_xlpm.memFinal&" + "&_xlpm.adicoesTxt)) )} | AM8: =_xlfn.TEXTJOIN("|",TRUE,A8,"Ativo","Circulante") -> Clientes|Ativo|Circulante | AN8: =_xlfn.CONCAT(S8,"|","DRE","|","DRE",) -> -Custo de Produtos Vendidos|DRE|DRE
A9: Clientes - Grupo | B9: =IFERROR(SUMIFS(INDEX(rastreabilidade!$F:$H,0,MATCH($B$2,rastreabilidade!$F$1:$H$1,0)),rastreabilidade!$K:$K,$A9,rastreabilidade!$D:$D,"Sim"),0) -> 0 | E9: =IFERROR(SUMIFS(INDEX(rastreabilidade!$F:$H,0,MATCH(E$3,rastreabilidade!$F$1:$H$1,0)),rastreabilidade!$N:$N,$AM9),0) +IF($N9="",0,IFERROR(SUMIFS(INDEX(rastreabilidade!$F:$H,0,MATCH(E$3,rastreabilidade!$F$1:$H$1,0)),rastreabilidade!$M:$M,$N9),0)) +IF($O9="",0,IFERROR(SUMIFS(INDEX(rastreabilidade!$F:$H,0,MATCH(E$3,rastreabilidade!$F$1:$H$1,0)),rastreabilidade!$M:$M,$O9),0)) +IF($P9="",0,IFERROR(SUMIFS(INDEX(rastreabilidade!$F:$H,0,MATCH(E$3,rastreabilidade!$F$1:$H$1,0)),rastreabilidade!$M:$M,$P9),0)) +IF($Q9="",0,IFERROR(SUMIFS(INDEX(rastreabilidade!$F:$H,0,MATCH(E$3,rastreabilidade!$F$1:$H$1,0)),rastreabilidade!$M:$M,$Q9),0)) -IF($J9="",0,IFERROR(SUMIFS(INDEX(rastreabilidade!$F:$H,0,MATCH(E$3,rastreabilidade!$F$1:$H$1,0)),rastreabilidade!$M:$M,$J9,rastreabilidade!$N:$N,$AM9),0)) -IF($K9="",0,IFERROR(SUMIFS(INDEX(rastreabilidade!$F:$H,0,MATCH(E$3,rastreabilidade!$F$1:$H$1,0)),rastreabilidade!$M:$M,$K9,rastreabilidade!$N:$N,$AM9),0)) -IF($L9="",0,IFERROR(SUMIFS(INDEX(rastreabilidade!$F:$H,0,MATCH(E$3,rastreabilidade!$F$1:$H$1,0)),rastreabilidade!$M:$M,$L9,rastreabilidade!$N:$N,$AM9),0)) -IF($M9="",0,IFERROR(SUMIFS(INDEX(rastreabilidade!$F:$H,0,MATCH(E$3,rastreabilidade!$F$1:$H$1,0)),rastreabilidade!$M:$M,$M9,rastreabilidade!$N:$N,$AM9),0)) -> 0 | F9: =IFERROR(SUMIFS(INDEX(rastreabilidade!$F:$H,0,MATCH(F$3,rastreabilidade!$F$1:$H$1,0)),rastreabilidade!$N:$N,$AM9),0) +IF($N9="",0,IFERROR(SUMIFS(INDEX(rastreabilidade!$F:$H,0,MATCH(F$3,rastreabilidade!$F$1:$H$1,0)),rastreabilidade!$M:$M,$N9),0)) +IF($O9="",0,IFERROR(SUMIFS(INDEX(rastreabilidade!$F:$H,0,MATCH(F$3,rastreabilidade!$F$1:$H$1,0)),rastreabilidade!$M:$M,$O9),0)) +IF($P9="",0,IFERROR(SUMIFS(INDEX(rastreabilidade!$F:$H,0,MATCH(F$3,rastreabilidade!$F$1:$H$1,0)),rastreabilidade!$M:$M,$P9),0)) +IF($Q9="",0,IFERROR(SUMIFS(INDEX(rastreabilidade!$F:$H,0,MATCH(F$3,rastreabilidade!$F$1:$H$1,0)),rastreabilidade!$M:$M,$Q9),0)) -IF($J9="",0,IFERROR(SUMIFS(INDEX(rastreabilidade!$F:$H,0,MATCH(F$3,rastreabilidade!$F$1:$H$1,0)),rastreabilidade!$M:$M,$J9,rastreabilidade!$N:$N,$AM9),0)) -IF($K9="",0,IFERROR(SUMIFS(INDEX(rastreabilidade!$F:$H,0,MATCH(F$3,rastreabilidade!$F$1:$H$1,0)),rastreabilidade!$M:$M,$K9,rastreabilidade!$N:$N,$AM9),0)) -IF($L9="",0,IFERROR(SUMIFS(INDEX(rastreabilidade!$F:$H,0,MATCH(F$3,rastreabilidade!$F$1:$H$1,0)),rastreabilidade!$M:$M,$L9,rastreabilidade!$N:$N,$AM9),0)) -IF($M9="",0,IFERROR(SUMIFS(INDEX(rastreabilidade!$F:$H,0,MATCH(F$3,rastreabilidade!$F$1:$H$1,0)),rastreabilidade!$M:$M,$M9,rastreabilidade!$N:$N,$AM9),0)) -> 0 | G9: =IFERROR(SUMIFS(INDEX(rastreabilidade!$F:$H,0,MATCH(G$3,rastreabilidade!$F$1:$H$1,0)),rastreabilidade!$N:$N,$AM9),0) +IF($N9="",0,IFERROR(SUMIFS(INDEX(rastreabilidade!$F:$H,0,MATCH(G$3,rastreabilidade!$F$1:$H$1,0)),rastreabilidade!$M:$M,$N9),0)) +IF($O9="",0,IFERROR(SUMIFS(INDEX(rastreabilidade!$F:$H,0,MATCH(G$3,rastreabilidade!$F$1:$H$1,0)),rastreabilidade!$M:$M,$O9),0)) +IF($P9="",0,IFERROR(SUMIFS(INDEX(rastreabilidade!$F:$H,0,MATCH(G$3,rastreabilidade!$F$1:$H$1,0)),rastreabilidade!$M:$M,$P9),0)) +IF($Q9="",0,IFERROR(SUMIFS(INDEX(rastreabilidade!$F:$H,0,MATCH(G$3,rastreabilidade!$F$1:$H$1,0)),rastreabilidade!$M:$M,$Q9),0)) -IF($J9="",0,IFERROR(SUMIFS(INDEX(rastreabilidade!$F:$H,0,MATCH(G$3,rastreabilidade!$F$1:$H$1,0)),rastreabilidade!$M:$M,$J9,rastreabilidade!$N:$N,$AM9),0)) -IF($K9="",0,IFERROR(SUMIFS(INDEX(rastreabilidade!$F:$H,0,MATCH(G$3,rastreabilidade!$F$1:$H$1,0)),rastreabilidade!$M:$M,$K9,rastreabilidade!$N:$N,$AM9),0)) -IF($L9="",0,IFERROR(SUMIFS(INDEX(rastreabilidade!$F:$H,0,MATCH(G$3,rastreabilidade!$F$1:$H$1,0)),rastreabilidade!$M:$M,$L9,rastreabilidade!$N:$N,$AM9),0)) -IF($M9="",0,IFERROR(SUMIFS(INDEX(rastreabilidade!$F:$H,0,MATCH(G$3,rastreabilidade!$F$1:$H$1,0)),rastreabilidade!$M:$M,$M9,rastreabilidade!$N:$N,$AM9),0)) -> 0 | I9: {=_xlfn.LET( _xlpm.mem,H9, _xlpm.retiradas,J9:M9, _xlpm.adicoes,N9:Q9, _xlpm.memAjustada,_xlfn.REDUCE(_xlpm.mem,_xlpm.retiradas,_xlfn.LAMBDA(_xlpm.x,_xlpm.y,IF(_xlpm.y<>"",SUBSTITUTE(_xlpm.x," + ("&_xlpm.y&")",""),_xlpm.x))), _xlpm.memRemovida,_xlfn.REDUCE(_xlpm.memAjustada,_xlpm.retiradas,_xlfn.LAMBDA(_xlpm.x,_xlpm.y,IF(_xlpm.y<>"",SUBSTITUTE(_xlpm.x,"("&_xlpm.y&")",""),_xlpm.x))), _xlpm.memSemSinal,IF(OR(LEFT(_xlpm.memRemovida,3)=" + ",LEFT(_xlpm.memRemovida,3)=" - "),MID(_xlpm.memRemovida,4,LEN(_xlpm.memRemovida)),_xlpm.memRemovida), _xlpm.memFinal,IF(OR(RIGHT(_xlpm.memSemSinal,3)=" + ",RIGHT(_xlpm.memSemSinal,3)=" - "),LEFT(_xlpm.memSemSinal,LEN(_xlpm.memSemSinal)-3),_xlpm.memSemSinal), _xlpm.adicoesTxt,_xlfn.TEXTJOIN(" + ",TRUE,IF(_xlpm.adicoes<>"","("&_xlpm.adicoes&")","")), IF(_xlpm.memFinal="",_xlpm.adicoesTxt,IF(_xlpm.adicoesTxt="",_xlpm.memFinal,_xlpm.memFinal&" + "&_xlpm.adicoesTxt)) )} | S9: Resultado Bruto | T9: =+T7-T8 -> 0 | W9: =+W7-W8 -> 0 | X9: =+X7-X8 -> 0 | Y9: =+Y7-Y8 -> 0 | AM9: =_xlfn.TEXTJOIN("|",TRUE,A9,"Ativo","Circulante") -> Clientes - Grupo|Ativo|Circulante | AN9: =_xlfn.CONCAT(S9,"|","DRE","|","DRE",) -> Resultado Bruto|DRE|DRE
A10: -PDD | B10: =IFERROR(SUMIFS(INDEX(rastreabilidade!$F:$H,0,MATCH($B$2,rastreabilidade!$F$1:$H$1,0)),rastreabilidade!$K:$K,$A10,rastreabilidade!$D:$D,"Sim"),0) -> 0 | E10: =IFERROR(SUMIFS(INDEX(rastreabilidade!$F:$H,0,MATCH(E$3,rastreabilidade!$F$1:$H$1,0)),rastreabilidade!$N:$N,$AM10),0) +IF($N10="",0,IFERROR(SUMIFS(INDEX(rastreabilidade!$F:$H,0,MATCH(E$3,rastreabilidade!$F$1:$H$1,0)),rastreabilidade!$M:$M,$N10),0)) +IF($O10="",0,IFERROR(SUMIFS(INDEX(rastreabilidade!$F:$H,0,MATCH(E$3,rastreabilidade!$F$1:$H$1,0)),rastreabilidade!$M:$M,$O10),0)) +IF($P10="",0,IFERROR(SUMIFS(INDEX(rastreabilidade!$F:$H,0,MATCH(E$3,rastreabilidade!$F$1:$H$1,0)),rastreabilidade!$M:$M,$P10),0)) +IF($Q10="",0,IFERROR(SUMIFS(INDEX(rastreabilidade!$F:$H,0,MATCH(E$3,rastreabilidade!$F$1:$H$1,0)),rastreabilidade!$M:$M,$Q10),0)) -IF($J10="",0,IFERROR(SUMIFS(INDEX(rastreabilidade!$F:$H,0,MATCH(E$3,rastreabilidade!$F$1:$H$1,0)),rastreabilidade!$M:$M,$J10,rastreabilidade!$N:$N,$AM10),0)) -IF($K10="",0,IFERROR(SUMIFS(INDEX(rastreabilidade!$F:$H,0,MATCH(E$3,rastreabilidade!$F$1:$H$1,0)),rastreabilidade!$M:$M,$K10,rastreabilidade!$N:$N,$AM10),0)) -IF($L10="",0,IFERROR(SUMIFS(INDEX(rastreabilidade!$F:$H,0,MATCH(E$3,rastreabilidade!$F$1:$H$1,0)),rastreabilidade!$M:$M,$L10,rastreabilidade!$N:$N,$AM10),0)) -IF($M10="",0,IFERROR(SUMIFS(INDEX(rastreabilidade!$F:$H,0,MATCH(E$3,rastreabilidade!$F$1:$H$1,0)),rastreabilidade!$M:$M,$M10,rastreabilidade!$N:$N,$AM10),0)) -> 0 | F10: =IFERROR(SUMIFS(INDEX(rastreabilidade!$F:$H,0,MATCH(F$3,rastreabilidade!$F$1:$H$1,0)),rastreabilidade!$N:$N,$AM10),0) +IF($N10="",0,IFERROR(SUMIFS(INDEX(rastreabilidade!$F:$H,0,MATCH(F$3,rastreabilidade!$F$1:$H$1,0)),rastreabilidade!$M:$M,$N10),0)) +IF($O10="",0,IFERROR(SUMIFS(INDEX(rastreabilidade!$F:$H,0,MATCH(F$3,rastreabilidade!$F$1:$H$1,0)),rastreabilidade!$M:$M,$O10),0)) +IF($P10="",0,IFERROR(SUMIFS(INDEX(rastreabilidade!$F:$H,0,MATCH(F$3,rastreabilidade!$F$1:$H$1,0)),rastreabilidade!$M:$M,$P10),0)) +IF($Q10="",0,IFERROR(SUMIFS(INDEX(rastreabilidade!$F:$H,0,MATCH(F$3,rastreabilidade!$F$1:$H$1,0)),rastreabilidade!$M:$M,$Q10),0)) -IF($J10="",0,IFERROR(SUMIFS(INDEX(rastreabilidade!$F:$H,0,MATCH(F$3,rastreabilidade!$F$1:$H$1,0)),rastreabilidade!$M:$M,$J10,rastreabilidade!$N:$N,$AM10),0)) -IF($K10="",0,IFERROR(SUMIFS(INDEX(rastreabilidade!$F:$H,0,MATCH(F$3,rastreabilidade!$F$1:$H$1,0)),rastreabilidade!$M:$M,$K10,rastreabilidade!$N:$N,$AM10),0)) -IF($L10="",0,IFERROR(SUMIFS(INDEX(rastreabilidade!$F:$H,0,MATCH(F$3,rastreabilidade!$F$1:$H$1,0)),rastreabilidade!$M:$M,$L10,rastreabilidade!$N:$N,$AM10),0)) -IF($M10="",0,IFERROR(SUMIFS(INDEX(rastreabilidade!$F:$H,0,MATCH(F$3,rastreabilidade!$F$1:$H$1,0)),rastreabilidade!$M:$M,$M10,rastreabilidade!$N:$N,$AM10),0)) -> 0 | G10: =IFERROR(SUMIFS(INDEX(rastreabilidade!$F:$H,0,MATCH(G$3,rastreabilidade!$F$1:$H$1,0)),rastreabilidade!$N:$N,$AM10),0) +IF($N10="",0,IFERROR(SUMIFS(INDEX(rastreabilidade!$F:$H,0,MATCH(G$3,rastreabilidade!$F$1:$H$1,0)),rastreabilidade!$M:$M,$N10),0)) +IF($O10="",0,IFERROR(SUMIFS(INDEX(rastreabilidade!$F:$H,0,MATCH(G$3,rastreabilidade!$F$1:$H$1,0)),rastreabilidade!$M:$M,$O10),0)) +IF($P10="",0,IFERROR(SUMIFS(INDEX(rastreabilidade!$F:$H,0,MATCH(G$3,rastreabilidade!$F$1:$H$1,0)),rastreabilidade!$M:$M,$P10),0)) +IF($Q10="",0,IFERROR(SUMIFS(INDEX(rastreabilidade!$F:$H,0,MATCH(G$3,rastreabilidade!$F$1:$H$1,0)),rastreabilidade!$M:$M,$Q10),0)) -IF($J10="",0,IFERROR(SUMIFS(INDEX(rastreabilidade!$F:$H,0,MATCH(G$3,rastreabilidade!$F$1:$H$1,0)),rastreabilidade!$M:$M,$J10,rastreabilidade!$N:$N,$AM10),0)) -IF($K10="",0,IFERROR(SUMIFS(INDEX(rastreabilidade!$F:$H,0,MATCH(G$3,rastreabilidade!$F$1:$H$1,0)),rastreabilidade!$M:$M,$K10,rastreabilidade!$N:$N,$AM10),0)) -IF($L10="",0,IFERROR(SUMIFS(INDEX(rastreabilidade!$F:$H,0,MATCH(G$3,rastreabilidade!$F$1:$H$1,0)),rastreabilidade!$M:$M,$L10,rastreabilidade!$N:$N,$AM10),0)) -IF($M10="",0,IFERROR(SUMIFS(INDEX(rastreabilidade!$F:$H,0,MATCH(G$3,rastreabilidade!$F$1:$H$1,0)),rastreabilidade!$M:$M,$M10,rastreabilidade!$N:$N,$AM10),0)) -> 0 | I10: {=_xlfn.LET( _xlpm.mem,H10, _xlpm.retiradas,J10:M10, _xlpm.adicoes,N10:Q10, _xlpm.memAjustada,_xlfn.REDUCE(_xlpm.mem,_xlpm.retiradas,_xlfn.LAMBDA(_xlpm.x,_xlpm.y,IF(_xlpm.y<>"",SUBSTITUTE(_xlpm.x," + ("&_xlpm.y&")",""),_xlpm.x))), _xlpm.memRemovida,_xlfn.REDUCE(_xlpm.memAjustada,_xlpm.retiradas,_xlfn.LAMBDA(_xlpm.x,_xlpm.y,IF(_xlpm.y<>"",SUBSTITUTE(_xlpm.x,"("&_xlpm.y&")",""),_xlpm.x))), _xlpm.memSemSinal,IF(OR(LEFT(_xlpm.memRemovida,3)=" + ",LEFT(_xlpm.memRemovida,3)=" - "),MID(_xlpm.memRemovida,4,LEN(_xlpm.memRemovida)),_xlpm.memRemovida), _xlpm.memFinal,IF(OR(RIGHT(_xlpm.memSemSinal,3)=" + ",RIGHT(_xlpm.memSemSinal,3)=" - "),LEFT(_xlpm.memSemSinal,LEN(_xlpm.memSemSinal)-3),_xlpm.memSemSinal), _xlpm.adicoesTxt,_xlfn.TEXTJOIN(" + ",TRUE,IF(_xlpm.adicoes<>"","("&_xlpm.adicoes&")","")), IF(_xlpm.memFinal="",_xlpm.adicoesTxt,IF(_xlpm.adicoesTxt="",_xlpm.memFinal,_xlpm.memFinal&" + "&_xlpm.adicoesTxt)) )} | S10: - Despesas com Vendas | T10: =IFERROR(SUMIFS(INDEX(rastreabilidade!$F:$H,0,MATCH($T$2,rastreabilidade!$F$1:$H$1,0)),rastreabilidade!$K:$K,$S10,rastreabilidade!$D:$D,"Sim"),0) -> 0 | W10: =IFERROR(SUMIFS(INDEX(rastreabilidade!$F:$H,0,MATCH(W$3,rastreabilidade!$F$1:$H$1,0)),rastreabilidade!$N:$N,$AN10),0)*IF($AB10="sim",-1,1) +IF($AG10="",0,IFERROR(SUMIFS(INDEX(rastreabilidade!$F:$H,0,MATCH(W$3,rastreabilidade!$F$1:$H$1,0)),rastreabilidade!$M:$M,$AG10),0)) +IF($AH10="",0,IFERROR(SUMIFS(INDEX(rastreabilidade!$F:$H,0,MATCH(W$3,rastreabilidade!$F$1:$H$1,0)),rastreabilidade!$M:$M,$AH10),0)) +IF($AI10="",0,IFERROR(SUMIFS(INDEX(rastreabilidade!$F:$H,0,MATCH(W$3,rastreabilidade!$F$1:$H$1,0)),rastreabilidade!$M:$M,$AI10),0)) +IF($AJ10="",0,IFERROR(SUMIFS(INDEX(rastreabilidade!$F:$H,0,MATCH(W$3,rastreabilidade!$F$1:$H$1,0)),rastreabilidade!$M:$M,$AJ10),0)) -IF($AC10="",0,IFERROR(SUMIFS(INDEX(rastreabilidade!$F:$H,0,MATCH(W$3,rastreabilidade!$F$1:$H$1,0)),rastreabilidade!$M:$M,$AC10,rastreabilidade!$N:$N,$AN10),0)) -IF($AD10="",0,IFERROR(SUMIFS(INDEX(rastreabilidade!$F:$H,0,MATCH(W$3,rastreabilidade!$F$1:$H$1,0)),rastreabilidade!$M:$M,$AD10,rastreabilidade!$N:$N,$AN10),0)) -IF($AE10="",0,IFERROR(SUMIFS(INDEX(rastreabilidade!$F:$H,0,MATCH(W$3,rastreabilidade!$F$1:$H$1,0)),rastreabilidade!$M:$M,$AE10,rastreabilidade!$N:$N,$AN10),0)) -IF($AF10="",0,IFERROR(SUMIFS(INDEX(rastreabilidade!$F:$H,0,MATCH(W$3,rastreabilidade!$F$1:$H$1,0)),rastreabilidade!$M:$M,$AF10,rastreabilidade!$N:$N,$AN10),0)) -> 0 | X10: =IFERROR(SUMIFS(INDEX(rastreabilidade!$F:$H,0,MATCH(X$3,rastreabilidade!$F$1:$H$1,0)),rastreabilidade!$N:$N,$AN10),0)*IF($AB10="sim",-1,1) +IF($AG10="",0,IFERROR(SUMIFS(INDEX(rastreabilidade!$F:$H,0,MATCH(X$3,rastreabilidade!$F$1:$H$1,0)),rastreabilidade!$M:$M,$AG10),0)) +IF($AH10="",0,IFERROR(SUMIFS(INDEX(rastreabilidade!$F:$H,0,MATCH(X$3,rastreabilidade!$F$1:$H$1,0)),rastreabilidade!$M:$M,$AH10),0)) +IF($AI10="",0,IFERROR(SUMIFS(INDEX(rastreabilidade!$F:$H,0,MATCH(X$3,rastreabilidade!$F$1:$H$1,0)),rastreabilidade!$M:$M,$AI10),0)) +IF($AJ10="",0,IFERROR(SUMIFS(INDEX(rastreabilidade!$F:$H,0,MATCH(X$3,rastreabilidade!$F$1:$H$1,0)),rastreabilidade!$M:$M,$AJ10),0)) -IF($AC10="",0,IFERROR(SUMIFS(INDEX(rastreabilidade!$F:$H,0,MATCH(X$3,rastreabilidade!$F$1:$H$1,0)),rastreabilidade!$M:$M,$AC10,rastreabilidade!$N:$N,$AN10),0)) -IF($AD10="",0,IFERROR(SUMIFS(INDEX(rastreabilidade!$F:$H,0,MATCH(X$3,rastreabilidade!$F$1:$H$1,0)),rastreabilidade!$M:$M,$AD10,rastreabilidade!$N:$N,$AN10),0)) -IF($AE10="",0,IFERROR(SUMIFS(INDEX(rastreabilidade!$F:$H,0,MATCH(X$3,rastreabilidade!$F$1:$H$1,0)),rastreabilidade!$M:$M,$AE10,rastreabilidade!$N:$N,$AN10),0)) -IF($AF10="",0,IFERROR(SUMIFS(INDEX(rastreabilidade!$F:$H,0,MATCH(X$3,rastreabilidade!$F$1:$H$1,0)),rastreabilidade!$M:$M,$AF10,rastreabilidade!$N:$N,$AN10),0)) -> 0 | Y10: =IFERROR(SUMIFS(INDEX(rastreabilidade!$F:$H,0,MATCH(Y$3,rastreabilidade!$F$1:$H$1,0)),rastreabilidade!$N:$N,$AN10),0)*IF($AB10="sim",-1,1) +IF($AG10="",0,IFERROR(SUMIFS(INDEX(rastreabilidade!$F:$H,0,MATCH(Y$3,rastreabilidade!$F$1:$H$1,0)),rastreabilidade!$M:$M,$AG10),0)) +IF($AH10="",0,IFERROR(SUMIFS(INDEX(rastreabilidade!$F:$H,0,MATCH(Y$3,rastreabilidade!$F$1:$H$1,0)),rastreabilidade!$M:$M,$AH10),0)) +IF($AI10="",0,IFERROR(SUMIFS(INDEX(rastreabilidade!$F:$H,0,MATCH(Y$3,rastreabilidade!$F$1:$H$1,0)),rastreabilidade!$M:$M,$AI10),0)) +IF($AJ10="",0,IFERROR(SUMIFS(INDEX(rastreabilidade!$F:$H,0,MATCH(Y$3,rastreabilidade!$F$1:$H$1,0)),rastreabilidade!$M:$M,$AJ10),0)) -IF($AC10="",0,IFERROR(SUMIFS(INDEX(rastreabilidade!$F:$H,0,MATCH(Y$3,rastreabilidade!$F$1:$H$1,0)),rastreabilidade!$M:$M,$AC10,rastreabilidade!$N:$N,$AN10),0)) -IF($AD10="",0,IFERROR(SUMIFS(INDEX(rastreabilidade!$F:$H,0,MATCH(Y$3,rastreabilidade!$F$1:$H$1,0)),rastreabilidade!$M:$M,$AD10,rastreabilidade!$N:$N,$AN10),0)) -IF($AE10="",0,IFERROR(SUMIFS(INDEX(rastreabilidade!$F:$H,0,MATCH(Y$3,rastreabilidade!$F$1:$H$1,0)),rastreabilidade!$M:$M,$AE10,rastreabilidade!$N:$N,$AN10),0)) -IF($AF10="",0,IFERROR(SUMIFS(INDEX(rastreabilidade!$F:$H,0,MATCH(Y$3,rastreabilidade!$F$1:$H$1,0)),rastreabilidade!$M:$M,$AF10,rastreabilidade!$N:$N,$AN10),0)) -> 0 | AA10: {=_xlfn.LET( _xlpm.mem,Z10, _xlpm.retiradas,AC10:AF10, _xlpm.adicoes,AG10:AJ10, _xlpm.memAjustada,_xlfn.REDUCE(_xlpm.mem,_xlpm.retiradas,_xlfn.LAMBDA(_xlpm.x,_xlpm.y,IF(_xlpm.y<>"",SUBSTITUTE(_xlpm.x," + ("&_xlpm.y&")",""),_xlpm.x))), _xlpm.memRemovida,_xlfn.REDUCE(_xlpm.memAjustada,_xlpm.retiradas,_xlfn.LAMBDA(_xlpm.x,_xlpm.y,IF(_xlpm.y<>"",SUBSTITUTE(_xlpm.x,"("&_xlpm.y&")",""),_xlpm.x))), _xlpm.memSemSinal,IF(OR(LEFT(_xlpm.memRemovida,3)=" + ",LEFT(_xlpm.memRemovida,3)=" - "),MID(_xlpm.memRemovida,4,LEN(_xlpm.memRemovida)),_xlpm.memRemovida), _xlpm.memFinal,IF(OR(RIGHT(_xlpm.memSemSinal,3)=" + ",RIGHT(_xlpm.memSemSinal,3)=" - "),LEFT(_xlpm.memSemSinal,LEN(_xlpm.memSemSinal)-3),_xlpm.memSemSinal), _xlpm.adicoesTxt,_xlfn.TEXTJOIN(" + ",TRUE,IF(_xlpm.adicoes<>"","("&_xlpm.adicoes&")","")), IF(_xlpm.memFinal="",_xlpm.adicoesTxt,IF(_xlpm.adicoesTxt="",_xlpm.memFinal,_xlpm.memFinal&" + "&_xlpm.adicoesTxt)) )} | AM10: =_xlfn.TEXTJOIN("|",TRUE,A10,"Ativo","Circulante") -> -PDD|Ativo|Circulante | AN10: =_xlfn.CONCAT(S10,"|","DRE","|","DRE",) -> - Despesas com Vendas|DRE|DRE
A11: Clientes Líquido | B11: =+B8+B9-B10 -> 0 | E11: =+E8+E9-E10 -> 0 | F11: =+F8+F9-F10 -> 0 | G11: =+G8+G9-G10 -> 0 | J11: =+J8+J9-J10 -> 0 | Q11: =+Q8+Q9-Q10 -> 0 | S11: - Despesas Administrativas | T11: =IFERROR(SUMIFS(INDEX(rastreabilidade!$F:$H,0,MATCH($T$2,rastreabilidade!$F$1:$H$1,0)),rastreabilidade!$K:$K,$S11,rastreabilidade!$D:$D,"Sim"),0) -> 0 | W11: =IFERROR(SUMIFS(INDEX(rastreabilidade!$F:$H,0,MATCH(W$3,rastreabilidade!$F$1:$H$1,0)),rastreabilidade!$N:$N,$AN11),0)*IF($AB11="sim",-1,1) +IF($AG11="",0,IFERROR(SUMIFS(INDEX(rastreabilidade!$F:$H,0,MATCH(W$3,rastreabilidade!$F$1:$H$1,0)),rastreabilidade!$M:$M,$AG11),0)) +IF($AH11="",0,IFERROR(SUMIFS(INDEX(rastreabilidade!$F:$H,0,MATCH(W$3,rastreabilidade!$F$1:$H$1,0)),rastreabilidade!$M:$M,$AH11),0)) +IF($AI11="",0,IFERROR(SUMIFS(INDEX(rastreabilidade!$F:$H,0,MATCH(W$3,rastreabilidade!$F$1:$H$1,0)),rastreabilidade!$M:$M,$AI11),0)) +IF($AJ11="",0,IFERROR(SUMIFS(INDEX(rastreabilidade!$F:$H,0,MATCH(W$3,rastreabilidade!$F$1:$H$1,0)),rastreabilidade!$M:$M,$AJ11),0)) -IF($AC11="",0,IFERROR(SUMIFS(INDEX(rastreabilidade!$F:$H,0,MATCH(W$3,rastreabilidade!$F$1:$H$1,0)),rastreabilidade!$M:$M,$AC11,rastreabilidade!$N:$N,$AN11),0)) -IF($AD11="",0,IFERROR(SUMIFS(INDEX(rastreabilidade!$F:$H,0,MATCH(W$3,rastreabilidade!$F$1:$H$1,0)),rastreabilidade!$M:$M,$AD11,rastreabilidade!$N:$N,$AN11),0)) -IF($AE11="",0,IFERROR(SUMIFS(INDEX(rastreabilidade!$F:$H,0,MATCH(W$3,rastreabilidade!$F$1:$H$1,0)),rastreabilidade!$M:$M,$AE11,rastreabilidade!$N:$N,$AN11),0)) -IF($AF11="",0,IFERROR(SUMIFS(INDEX(rastreabilidade!$F:$H,0,MATCH(W$3,rastreabilidade!$F$1:$H$1,0)),rastreabilidade!$M:$M,$AF11,rastreabilidade!$N:$N,$AN11),0)) -> 0 | X11: =IFERROR(SUMIFS(INDEX(rastreabilidade!$F:$H,0,MATCH(X$3,rastreabilidade!$F$1:$H$1,0)),rastreabilidade!$N:$N,$AN11),0)*IF($AB11="sim",-1,1) +IF($AG11="",0,IFERROR(SUMIFS(INDEX(rastreabilidade!$F:$H,0,MATCH(X$3,rastreabilidade!$F$1:$H$1,0)),rastreabilidade!$M:$M,$AG11),0)) +IF($AH11="",0,IFERROR(SUMIFS(INDEX(rastreabilidade!$F:$H,0,MATCH(X$3,rastreabilidade!$F$1:$H$1,0)),rastreabilidade!$M:$M,$AH11),0)) +IF($AI11="",0,IFERROR(SUMIFS(INDEX(rastreabilidade!$F:$H,0,MATCH(X$3,rastreabilidade!$F$1:$H$1,0)),rastreabilidade!$M:$M,$AI11),0)) +IF($AJ11="",0,IFERROR(SUMIFS(INDEX(rastreabilidade!$F:$H,0,MATCH(X$3,rastreabilidade!$F$1:$H$1,0)),rastreabilidade!$M:$M,$AJ11),0)) -IF($AC11="",0,IFERROR(SUMIFS(INDEX(rastreabilidade!$F:$H,0,MATCH(X$3,rastreabilidade!$F$1:$H$1,0)),rastreabilidade!$M:$M,$AC11,rastreabilidade!$N:$N,$AN11),0)) -IF($AD11="",0,IFERROR(SUMIFS(INDEX(rastreabilidade!$F:$H,0,MATCH(X$3,rastreabilidade!$F$1:$H$1,0)),rastreabilidade!$M:$M,$AD11,rastreabilidade!$N:$N,$AN11),0)) -IF($AE11="",0,IFERROR(SUMIFS(INDEX(rastreabilidade!$F:$H,0,MATCH(X$3,rastreabilidade!$F$1:$H$1,0)),rastreabilidade!$M:$M,$AE11,rastreabilidade!$N:$N,$AN11),0)) -IF($AF11="",0,IFERROR(SUMIFS(INDEX(rastreabilidade!$F:$H,0,MATCH(X$3,rastreabilidade!$F$1:$H$1,0)),rastreabilidade!$M:$M,$AF11,rastreabilidade!$N:$N,$AN11),0)) -> 0 | Y11: =IFERROR(SUMIFS(INDEX(rastreabilidade!$F:$H,0,MATCH(Y$3,rastreabilidade!$F$1:$H$1,0)),rastreabilidade!$N:$N,$AN11),0)*IF($AB11="sim",-1,1) +IF($AG11="",0,IFERROR(SUMIFS(INDEX(rastreabilidade!$F:$H,0,MATCH(Y$3,rastreabilidade!$F$1:$H$1,0)),rastreabilidade!$M:$M,$AG11),0)) +IF($AH11="",0,IFERROR(SUMIFS(INDEX(rastreabilidade!$F:$H,0,MATCH(Y$3,rastreabilidade!$F$1:$H$1,0)),rastreabilidade!$M:$M,$AH11),0)) +IF($AI11="",0,IFERROR(SUMIFS(INDEX(rastreabilidade!$F:$H,0,MATCH(Y$3,rastreabilidade!$F$1:$H$1,0)),rastreabilidade!$M:$M,$AI11),0)) +IF($AJ11="",0,IFERROR(SUMIFS(INDEX(rastreabilidade!$F:$H,0,MATCH(Y$3,rastreabilidade!$F$1:$H$1,0)),rastreabilidade!$M:$M,$AJ11),0)) -IF($AC11="",0,IFERROR(SUMIFS(INDEX(rastreabilidade!$F:$H,0,MATCH(Y$3,rastreabilidade!$F$1:$H$1,0)),rastreabilidade!$M:$M,$AC11,rastreabilidade!$N:$N,$AN11),0)) -IF($AD11="",0,IFERROR(SUMIFS(INDEX(rastreabilidade!$F:$H,0,MATCH(Y$3,rastreabilidade!$F$1:$H$1,0)),rastreabilidade!$M:$M,$AD11,rastreabilidade!$N:$N,$AN11),0)) -IF($AE11="",0,IFERROR(SUMIFS(INDEX(rastreabilidade!$F:$H,0,MATCH(Y$3,rastreabilidade!$F$1:$H$1,0)),rastreabilidade!$M:$M,$AE11,rastreabilidade!$N:$N,$AN11),0)) -IF($AF11="",0,IFERROR(SUMIFS(INDEX(rastreabilidade!$F:$H,0,MATCH(Y$3,rastreabilidade!$F$1:$H$1,0)),rastreabilidade!$M:$M,$AF11,rastreabilidade!$N:$N,$AN11),0)) -> 0 | AA11: {=_xlfn.LET( _xlpm.mem,Z11, _xlpm.retiradas,AC11:AF11, _xlpm.adicoes,AG11:AJ11, _xlpm.memAjustada,_xlfn.REDUCE(_xlpm.mem,_xlpm.retiradas,_xlfn.LAMBDA(_xlpm.x,_xlpm.y,IF(_xlpm.y<>"",SUBSTITUTE(_xlpm.x," + ("&_xlpm.y&")",""),_xlpm.x))), _xlpm.memRemovida,_xlfn.REDUCE(_xlpm.memAjustada,_xlpm.retiradas,_xlfn.LAMBDA(_xlpm.x,_xlpm.y,IF(_xlpm.y<>"",SUBSTITUTE(_xlpm.x,"("&_xlpm.y&")",""),_xlpm.x))), _xlpm.memSemSinal,IF(OR(LEFT(_xlpm.memRemovida,3)=" + ",LEFT(_xlpm.memRemovida,3)=" - "),MID(_xlpm.memRemovida,4,LEN(_xlpm.memRemovida)),_xlpm.memRemovida), _xlpm.memFinal,IF(OR(RIGHT(_xlpm.memSemSinal,3)=" + ",RIGHT(_xlpm.memSemSinal,3)=" - "),LEFT(_xlpm.memSemSinal,LEN(_xlpm.memSemSinal)-3),_xlpm.memSemSinal), _xlpm.adicoesTxt,_xlfn.TEXTJOIN(" + ",TRUE,IF(_xlpm.adicoes<>"","("&_xlpm.adicoes&")","")), IF(_xlpm.memFinal="",_xlpm.adicoesTxt,IF(_xlpm.adicoesTxt="",_xlpm.memFinal,_xlpm.memFinal&" + "&_xlpm.adicoesTxt)) )} | AM11: =_xlfn.TEXTJOIN("|",TRUE,A11,"Ativo","Circulante") -> Clientes Líquido|Ativo|Circulante | AN11: =_xlfn.CONCAT(S11,"|","DRE","|","DRE",) -> - Despesas Administrativas|DRE|DRE
A12: Matéria-Prima | B12: =IFERROR(SUMIFS(INDEX(rastreabilidade!$F:$H,0,MATCH($B$2,rastreabilidade!$F$1:$H$1,0)),rastreabilidade!$K:$K,$A12,rastreabilidade!$D:$D,"Sim"),0) -> 0 | E12: =IFERROR(SUMIFS(INDEX(rastreabilidade!$F:$H,0,MATCH(E$3,rastreabilidade!$F$1:$H$1,0)),rastreabilidade!$N:$N,$AM12),0) +IF($N12="",0,IFERROR(SUMIFS(INDEX(rastreabilidade!$F:$H,0,MATCH(E$3,rastreabilidade!$F$1:$H$1,0)),rastreabilidade!$M:$M,$N12),0)) +IF($O12="",0,IFERROR(SUMIFS(INDEX(rastreabilidade!$F:$H,0,MATCH(E$3,rastreabilidade!$F$1:$H$1,0)),rastreabilidade!$M:$M,$O12),0)) +IF($P12="",0,IFERROR(SUMIFS(INDEX(rastreabilidade!$F:$H,0,MATCH(E$3,rastreabilidade!$F$1:$H$1,0)),rastreabilidade!$M:$M,$P12),0)) +IF($Q12="",0,IFERROR(SUMIFS(INDEX(rastreabilidade!$F:$H,0,MATCH(E$3,rastreabilidade!$F$1:$H$1,0)),rastreabilidade!$M:$M,$Q12),0)) -IF($J12="",0,IFERROR(SUMIFS(INDEX(rastreabilidade!$F:$H,0,MATCH(E$3,rastreabilidade!$F$1:$H$1,0)),rastreabilidade!$M:$M,$J12,rastreabilidade!$N:$N,$AM12),0)) -IF($K12="",0,IFERROR(SUMIFS(INDEX(rastreabilidade!$F:$H,0,MATCH(E$3,rastreabilidade!$F$1:$H$1,0)),rastreabilidade!$M:$M,$K12,rastreabilidade!$N:$N,$AM12),0)) -IF($L12="",0,IFERROR(SUMIFS(INDEX(rastreabilidade!$F:$H,0,MATCH(E$3,rastreabilidade!$F$1:$H$1,0)),rastreabilidade!$M:$M,$L12,rastreabilidade!$N:$N,$AM12),0)) -IF($M12="",0,IFERROR(SUMIFS(INDEX(rastreabilidade!$F:$H,0,MATCH(E$3,rastreabilidade!$F$1:$H$1,0)),rastreabilidade!$M:$M,$M12,rastreabilidade!$N:$N,$AM12),0)) -> 0 | F12: =IFERROR(SUMIFS(INDEX(rastreabilidade!$F:$H,0,MATCH(F$3,rastreabilidade!$F$1:$H$1,0)),rastreabilidade!$N:$N,$AM12),0) +IF($N12="",0,IFERROR(SUMIFS(INDEX(rastreabilidade!$F:$H,0,MATCH(F$3,rastreabilidade!$F$1:$H$1,0)),rastreabilidade!$M:$M,$N12),0)) +IF($O12="",0,IFERROR(SUMIFS(INDEX(rastreabilidade!$F:$H,0,MATCH(F$3,rastreabilidade!$F$1:$H$1,0)),rastreabilidade!$M:$M,$O12),0)) +IF($P12="",0,IFERROR(SUMIFS(INDEX(rastreabilidade!$F:$H,0,MATCH(F$3,rastreabilidade!$F$1:$H$1,0)),rastreabilidade!$M:$M,$P12),0)) +IF($Q12="",0,IFERROR(SUMIFS(INDEX(rastreabilidade!$F:$H,0,MATCH(F$3,rastreabilidade!$F$1:$H$1,0)),rastreabilidade!$M:$M,$Q12),0)) -IF($J12="",0,IFERROR(SUMIFS(INDEX(rastreabilidade!$F:$H,0,MATCH(F$3,rastreabilidade!$F$1:$H$1,0)),rastreabilidade!$M:$M,$J12,rastreabilidade!$N:$N,$AM12),0)) -IF($K12="",0,IFERROR(SUMIFS(INDEX(rastreabilidade!$F:$H,0,MATCH(F$3,rastreabilidade!$F$1:$H$1,0)),rastreabilidade!$M:$M,$K12,rastreabilidade!$N:$N,$AM12),0)) -IF($L12="",0,IFERROR(SUMIFS(INDEX(rastreabilidade!$F:$H,0,MATCH(F$3,rastreabilidade!$F$1:$H$1,0)),rastreabilidade!$M:$M,$L12,rastreabilidade!$N:$N,$AM12),0)) -IF($M12="",0,IFERROR(SUMIFS(INDEX(rastreabilidade!$F:$H,0,MATCH(F$3,rastreabilidade!$F$1:$H$1,0)),rastreabilidade!$M:$M,$M12,rastreabilidade!$N:$N,$AM12),0)) -> 0 | G12: =IFERROR(SUMIFS(INDEX(rastreabilidade!$F:$H,0,MATCH(G$3,rastreabilidade!$F$1:$H$1,0)),rastreabilidade!$N:$N,$AM12),0) +IF($N12="",0,IFERROR(SUMIFS(INDEX(rastreabilidade!$F:$H,0,MATCH(G$3,rastreabilidade!$F$1:$H$1,0)),rastreabilidade!$M:$M,$N12),0)) +IF($O12="",0,IFERROR(SUMIFS(INDEX(rastreabilidade!$F:$H,0,MATCH(G$3,rastreabilidade!$F$1:$H$1,0)),rastreabilidade!$M:$M,$O12),0)) +IF($P12="",0,IFERROR(SUMIFS(INDEX(rastreabilidade!$F:$H,0,MATCH(G$3,rastreabilidade!$F$1:$H$1,0)),rastreabilidade!$M:$M,$P12),0)) +IF($Q12="",0,IFERROR(SUMIFS(INDEX(rastreabilidade!$F:$H,0,MATCH(G$3,rastreabilidade!$F$1:$H$1,0)),rastreabilidade!$M:$M,$Q12),0)) -IF($J12="",0,IFERROR(SUMIFS(INDEX(rastreabilidade!$F:$H,0,MATCH(G$3,rastreabilidade!$F$1:$H$1,0)),rastreabilidade!$M:$M,$J12,rastreabilidade!$N:$N,$AM12),0)) -IF($K12="",0,IFERROR(SUMIFS(INDEX(rastreabilidade!$F:$H,0,MATCH(G$3,rastreabilidade!$F$1:$H$1,0)),rastreabilidade!$M:$M,$K12,rastreabilidade!$N:$N,$AM12),0)) -IF($L12="",0,IFERROR(SUMIFS(INDEX(rastreabilidade!$F:$H,0,MATCH(G$3,rastreabilidade!$F$1:$H$1,0)),rastreabilidade!$M:$M,$L12,rastreabilidade!$N:$N,$AM12),0)) -IF($M12="",0,IFERROR(SUMIFS(INDEX(rastreabilidade!$F:$H,0,MATCH(G$3,rastreabilidade!$F$1:$H$1,0)),rastreabilidade!$M:$M,$M12,rastreabilidade!$N:$N,$AM12),0)) -> 0 | I12: {=_xlfn.LET( _xlpm.mem,H12, _xlpm.retiradas,J12:M12, _xlpm.adicoes,N12:Q12, _xlpm.memAjustada,_xlfn.REDUCE(_xlpm.mem,_xlpm.retiradas,_xlfn.LAMBDA(_xlpm.x,_xlpm.y,IF(_xlpm.y<>"",SUBSTITUTE(_xlpm.x," + ("&_xlpm.y&")",""),_xlpm.x))), _xlpm.memRemovida,_xlfn.REDUCE(_xlpm.memAjustada,_xlpm.retiradas,_xlfn.LAMBDA(_xlpm.x,_xlpm.y,IF(_xlpm.y<>"",SUBSTITUTE(_xlpm.x,"("&_xlpm.y&")",""),_xlpm.x))), _xlpm.memSemSinal,IF(OR(LEFT(_xlpm.memRemovida,3)=" + ",LEFT(_xlpm.memRemovida,3)=" - "),MID(_xlpm.memRemovida,4,LEN(_xlpm.memRemovida)),_xlpm.memRemovida), _xlpm.memFinal,IF(OR(RIGHT(_xlpm.memSemSinal,3)=" + ",RIGHT(_xlpm.memSemSinal,3)=" - "),LEFT(_xlpm.memSemSinal,LEN(_xlpm.memSemSinal)-3),_xlpm.memSemSinal), _xlpm.adicoesTxt,_xlfn.TEXTJOIN(" + ",TRUE,IF(_xlpm.adicoes<>"","("&_xlpm.adicoes&")","")), IF(_xlpm.memFinal="",_xlpm.adicoesTxt,IF(_xlpm.adicoesTxt="",_xlpm.memFinal,_xlpm.memFinal&" + "&_xlpm.adicoesTxt)) )} | S12: Resultado da Exploração | T12: =T9-T10-T11 -> 0 | W12: =W9-W10-W11 -> 0 | X12: =X9-X10-X11 -> 0 | Y12: =Y9-Y10-Y11 -> 0 | AM12: =_xlfn.TEXTJOIN("|",TRUE,A12,"Ativo","Circulante") -> Matéria-Prima|Ativo|Circulante | AN12: =_xlfn.CONCAT(S12,"|","DRE","|","DRE",) -> Resultado da Exploração |DRE|DRE
